Workbook

Sheet Slot 5  - dose
A1: WAFER ID | B1: Platform | D1: Reticle title | E1: Slot | F1: Wavelength | G1: Wg length
E2: 5
A4: No | B4: Waveguide | C4: Type | D4: Chip | E4: Propagation loss (dB/cm) | F4: MSE | G4: Date | H4: Status | I4: Comment | J4: Further action
A5: 1 | B5: Straight | D5: 8 | E5: 5.3469286 | F5: 0.03059289 | G5: 45813
A6: 2 | D6: 12 | E6: 8.6189027 | F6: 0.068842848
A7: 3 | D7: 16 | E7: 8.1633819 | F7: 0.051931011 | I7: wg5wg6 - fixed
A8: 4 | D8: 33 | E8: 4.795825 | F8: 0.033622595
A9: 5 | D9: 35 | E9: 5.2665889 | F9: 0.014916907
A10: 6 | D10: 37 | E10: 8.4013352 | F10: 0.13407392
A11: 7 | D11: 41 | E11: 8.002845 | F11: 0.036268594 | I11: wg6-fixed
A12: 8 | D12: 59 | E12: 5.7121413 | F12: 0.020440519
A13: 9 | D13: 61 | E13: 5.7012177 | F13: 0.067994551
A14: 10 | D14: 63 | E14: 6.7016685 | F14: 0.042181949
A15: 11 | D15: 67 | E15: 6.6207462 | F15: 0.075842604 | I15: wg6-fixed
A16: 12 | D16: 84 | E16: 5.5739141 | F16: 0.060228034 | I16: wg1-fixed
A17: 13 | D17: 88 | E17: 6.4793118 | F17: 0.065128094
A18: 14 | D18: 92 | E18: 8.6975148 | F18: 0.15427714 | I18: wg6-fixed
A22: Dose (mJ) | B22: Chip | C22: Loss (dB/cm) | D22: MSE
A23: 22 | B23: 12 | C23: 8.6189027 | D23: 0.068842848
B24: 16 | C24: 8.1633819 | D24: 0.051931011
B25: 37 | C25: 8.4013352 | D25: 0.13407392
B26: 41 | C26: 8.002845 | D26: 0.036268594
B27: AVERAGE | C27: =AVERAGE(C23:C26) -> 8.2966162
A28: 24 | B28: 63 | C28: 6.7016685 | D28: 0.042181949
B29: 67 | C29: 6.6207462 | D29: 0.075842604
B30: 88 | C30: 6.4793118 | D30: 0.065128094
B31: 92 | C31: 8.6975148 | D31: 0.15427714
B32: AVERAGE | C32: =AVERAGE(C28:C31) -> 7.1248103
A33: 26 | B33: 59 | C33: 5.7121413 | D33: 0.020440519
B34: 61 | C34: 5.7012177 | D34: 0.067994551
B35: 84 | C35: 5.5739141 | D35: 0.060228034
B36: AVERAGE | C36: =AVERAGE(C33:C35) -> 5.6624244
A37: 28 | B37: 8 | C37: 5.3469286 | D37: 0.03059289
B38: 33 | C38: 4.795825 | D38: 0.033622595
B39: 35 | C39: 5.2665889 | D39: 0.014916907
B40: AVERAGE | C40: =AVERAGE(C37:C39) -> 5.1364475

Sheet Slot 7 - dose
A1: WAFER ID | B1: Platform | D1: Reticle title | E1: Slot | F1: Wavelength | G1: Wg length
E2: 7
A4: No | B4: Waveguide | C4: Type | D4: Chip | E4: Propagation loss (dB/cm) | F4: MSE | G4: Date | H4: Status | I4: Comment | J4: Further action
A5: 1 | B5: Straight | D5: 8 | E5: 3.8016985 | F5: 0.065715203
A6: 2 | D6: 12 | E6: 4.5594944 | F6: 0.082247904
A7: 3 | D7: 16 | E7: 4.5676045 | F7: 0.031333235 | I7: wg6-fixed
A8: 4 | D8: 33 | E8: 3.9804323 | F8: 0.028292244
A9: 5 | D9: 35 | E9: 4.9293885 | F9: 0.03434945
A10: 6 | D10: 37 | E10: 7.3287725 | F10: 0.14295156 | I10: wg5-fixed
A11: 7 | D11: 41 | E11: 4.7918199 | F11: 0.018803199
A12: 8 | D12: 59 | E12: 4.6096069 | F12: 0.054239011
A13: 9 | D13: 63 | E13: 5.4052016 | F13: 0.011621006 | I13: wg6-fixed
A14: 10 | D14: 65 | E14: 4.6602055 | F14: 0.069539105 | I14: wg5-fixed
A15: 11 | D15: 67 | E15: 11.399911 | F15: 65.898217 | I15: wg5wg6-failed
A16: 12 | D16: 84 | E16: 13.160419 | F16: 103.22497 | I16: wg5wg6-failed
A17: 13 | D17: 88 | E17: 4.050786 | F17: 0.027279707
A18: 14 | D18: 92 | E18: 4.7759515 | F18: 0.0067731695 | I18: wg5wg6-fixed
A22: Dose (mJ) | B22: Chip | C22: Loss (dB/cm) | D22: MSE
A23: 22 | B23: 12 | C23: 4.5594944 | D23: 0.082247904
B24: 16 | C24: 4.5676045 | D24: 0.031333235
B25: 41 | C25: 4.7918199 | D25: 0.018803199
B26: AVERAGE | C26: =AVERAGE(C23:C25) -> 4.6396396
A27: 24 | B27: 63 | C27: 5.4052016 | D27: 0.011621006
B28: 65 | C28: 4.6602055 | D28: 0.069539105
B29: 88 | C29: 4.050786 | D29: 0.027279707
B30: 92 | C30: 4.7759515 | D30: 0.0067731695
B31: AVERAGE | C31: =AVERAGE(C27:C30) -> 4.7230361
A32: 26 | B32: 59 | C32: 4.6096069 | D32: 0.054239011
B33: 84
B34: AVERAGE | C34: =AVERAGE(C32:C33) -> 4.6096069
A35: 28 | B35: 8 | C35: 3.8016985 | D35: 0.065715203
B36: 33 | C36: 3.9804323 | D36: 0.028292244
B37: 35 | C37: 4.9293885 | D37: 0.03434945
B38: AVERAGE | C38: =AVERAGE(C35:C37) -> 4.2371731

Sheet Slot 11 - dose
A1: WAFER ID | B1: Platform | D1: Reticle title | E1: Slot | F1: Wavelength | G1: Wg length
E2: 7
A4: No | B4: Waveguide | C4: Type | D4: Chip | E4: Propagation loss (dB/cm) | F4: MSE | G4: Date | H4: Status | I4: Comment | J4: Further action
A5: 1 | B5: Straight | D5: 1 | E5: 4.7761623 | F5: 2.4443262 | I5: wg4,wg6
A6: 2 | D6: 33 | E6: 4.9059561 | F6: 0.045757777
A7: 3 | D7: 35 | E7: 5.0255103 | F7: 0.028879588
A8: 4 | D8: 37 | E8: 5.6724267 | F8: 0.013169828
A9: 5 | D9: 47 | E9: 5.0594241 | F9: 0.026731825
A10: 6 | D10: 54 | E10: 4.5212136 | F10: 0.0078438196
A11: 7 | D11: 58 | E11: 4.932193 | F11: 0.026034511
A12: 8 | D12: 76 | E12: 5.1447723 | F12: 0.018529104
A13: 9 | D13: 89 | E13: 4.4133392 | F13: 0.015171549
A14: 10 | D14: 95 | E14: 11.423871 | F14: 98.214409
A15: 11 | D15: 100 | E15: 5.6714595 | F15: 0.019404283
A16: 12
A17: 13
A18: 14
A22: Dose (mJ) | B22: Chip | C22: Loss (dB/cm) | D22: MSE
A23: 22 | B23: 37 | C23: 5.6724267 | D23: 0.013169828
B24: AVERAGE | C24: =AVERAGE(C23:C23) -> 5.6724267
A25: 24 | B25: 54 | C25: 4.5212136 | D25: 0.0078438196
B26: 76 | C26: 5.1447723 | D26: 0.018529104
B27: 89 | C27: 4.4133392 | D27: 0.015171549
B28: AVERAGE | C28: =AVERAGE(C25:C27) -> 4.6931084
A29: 26 | B29: 58 | C29: 4.932193 | D29: 0.026034511
B30: AVERAGE | C30: =AVERAGE(C29:C29) -> 4.932193
A31: 28 | B31: 1 | C31: 4.7761623 | D31: 2.4443262
B32: 33 | C32: 4.9059561 | D32: 0.045757777
B33: 35 | C33: 5.0255103 | D33: 0.028879588
B34: 47 | C34: 5.0594241 | D34: 0.026731825
B35: AVERAGE | C35: =AVERAGE(C31:C34) -> 4.9417632

Sheet Slot 12 - dose
A1: WAFER ID | B1: Platform | D1: Reticle title | E1: Slot | F1: Wavelength | G1: Wg length
E2: 7
A4: No | B4: Waveguide | C4: Type | D4: Chip | E4: Propagation loss (dB/cm) | F4: MSE | G4: Date | H4: Status | I4: Comment | J4: Further action
A5: 1 | B5: Straight | D5: 10 | E5: 3.0386561 | F5: 0.029479292
A6: 2 | D6: 24 | E6: 7.0545807 | F6: 0.20910891
A7: 3 | D7: 36 | E7: 7.559376 | F7: 0.33270249
A8: 4 | D8: 39 | E8: 6.8878792 | F8: 0.022577854
A9: 5 | D9: 48 | E9: 4.9315566 | F9: 0.016351369
A10: 6 | D10: 51 | E10: 6.2792691 | F10: 0.016077686
A11: 7 | D11: 54 | E11: 3.4768161 | F11: 0.006000173
A12: 8 | D12: 63 | E12: 5.2923086 | F12: 0.072220967
A13: 9 | D13: 72 | E13: 3.8239438 | F13: 0.056732106
A14: 10 | D14: 78 | E14: 4.0410067 | F14: 0.014557971
A15: 11
A16: 12
A17: 13
A18: 14
A22: Dose (mJ) | B22: Chip | C22: Loss (dB/cm) | D22: MSE
A23: 22 | B23: 24 | C23: 7.0545807 | D23: 0.20910891
B24: 36 | C24: 7.559376 | D24: 0.33270249
B25: 39 | C25: 6.8878792 | D25: 0.022577854
B26: AVERAGE | C26: =AVERAGE(C23:C25) -> 7.1672786
A27: 24 | B27: 51 | C27: 6.2792691 | D27: 0.016077686
B28: 54 | C28: 3.4768161 | D28: 0.006000173
B29: 63 | C29: 5.2923086 | D29: 0.072220967
B30: 78 | C30: 4.0410067 | D30: 0.014557971
B31: AVERAGE | C31: =AVERAGE(C27:C30) -> 4.7723501
A32: 26 | B32: 72 | C32: 3.8239438 | D32: 0.056732106
B33: AVERAGE | C33: =AVERAGE(C32:C32) -> 3.8239438
A34: 28 | B34: 10 | C34: 3.0386561 | D34: 0.029479292
B35: 48 | C35: 4.9315566 | D35: 0.016351369
B36: AVERAGE | C36: =AVERAGE(C34:C35) -> 3.9851063

Sheet Slot 15 - dose
A1: WAFER ID | B1: Platform | D1: Reticle title | E1: Slot | F1: Wavelength | G1: Wg length
E2: 7
A4: No | B4: Waveguide | C4: Type | D4: Chip | E4: Propagation loss (dB/cm) | F4: MSE | G4: Date | H4: Status | I4: Comment | J4: Further action
A5: 1 | B5: Straight | D5: 10 | E5: 3.5427982 | F5: 0.0428601
A6: 2 | D6: 24 | E6: 7.4253167 | F6: 0.057048755
A7: 3 | D7: 36 | E7: 10.701181 | F7: 0.88845084
A8: 4 | D8: 39 | E8: 7.2038043 | F8: 0.06626441
A9: 5 | D9: 45 | E9: 3.2774462 | F9: 0.015765017
A10: 6 | D10: 48 | E10: 6.1933853 | F10: 0.000465079
A11: 7 | D11: 51 | E11: 7.7869172 | F11: 0.008394457
A12: 8 | D12: 54 | E12: 6.2923482 | F12: 0.005710118
A13: 9 | D13: 63 | E13: 7.2757576 | F13: 0.059220969
A14: 10 | D14: 72 | E14: 4.1770588 | F14: 0.001844966
A15: 11 | D15: 78 | E15: 5.2635112 | F15: 0.011641517
A16: 12
A17: 13
A18: 14
A22: Dose (mJ) | B22: Chip | C22: Loss (dB/cm) | D22: MSE
A23: 22 | B23: 24 | C23: 7.4253167 | D23: 0.057048755
B24: 39 | C24: 7.2038043 | D24: 0.06626441
B25: AVERAGE | C25: =AVERAGE(C23:C24) -> 7.3145605
A26: 24 | B26: 51 | C26: 7.7869172 | D26: 0.008394457
B27: 54 | C27: 6.2923482 | D27: 0.005710118
B28: 63 | C28: 7.2757576 | D28: 0.059220969
B29: 78 | C29: 5.2635112 | D29: 0.011641517
B30: AVERAGE | C30: =AVERAGE(C26:C29) -> 6.6546335
A31: 26 | B31: 72 | C31: 4.1770588 | D31: 0.001844966
B32: AVERAGE | C32: =AVERAGE(C31:C31) -> 4.1770588
A33: 28 | B33: 10 | C33: 3.5427982 | D33: 0.0428601
B34: 48 | C34: 6.1933853 | D34: 0.000465079
B35: AVERAGE | C35: =AVERAGE(C33:C34) -> 4.8680917

Sheet Slot 16 - dose
A1: WAFER ID | B1: Platform | D1: Reticle title | E1: Slot | F1: Wavelength | G1: Wg length
E2: 16
A4: No | B4: Waveguide | C4: Type | D4: Chip | E4: Propagation loss (dB/cm) | F4: MSE | G4: Date | H4: Status | I4: Comment | J4: Further action
A5: 1 | B5: Straight | D5: 8 | E5: 4.1715902 | F5: 0.037808325 | G5: 45813
A6: 2 | D6: 12 | E6: 3.9908181 | F6: 0.049396966 | I6: wg5wg6-fixed
A7: 3 | D7: 16 | E7: 4.8290618 | F7: 0.060779595
A8: 4 | D8: 33 | E8: 4.4122907 | F8: 0.019374126
A9: 5 | D9: 35 | E9: 4.3408062 | F9: 0.045095185
A10: 6 | D10: 37 | E10: 5.0957503 | F10: 0.028705435
A11: 7 | D11: 41 | E11: 4.7250513 | F11: 0.014534886
A12: 8 | D12: 59 | E12: 4.8603508 | F12: 0.05301883
A13: 9 | D13: 61 | E13: 4.9682208 | F13: 0.014070932
A14: 10 | D14: 63 | E14: 4.824328 | F14: 0.021049147
A15: 11 | D15: 67 | E15: 4.1038373 | F15: 0.018351033
A16: 12 | D16: 84 | E16: 4.0153259 | F16: 0.02571563
A17: 13 | D17: 88 | E17: 4.045167 | F17: 0.010901527
A18: 14 | D18: 92 | E18: 5.1007059 | F18: 0.017906478
A22: Dose (mJ) | B22: Chip | C22: Loss (dB/cm) | D22: MSE
A23: 22 | B23: 12 | C23: 3.9908181 | D23: 0.049396966
B24: 16 | C24: 4.1715902 | D24: 0.037808325
B25: 37 | C25: 5.0957503 | D25: 0.028705435
B26: 41 | C26: 4.7250513 | D26: 0.014534886
B27: AVERAGE | C27: =AVERAGE(C23:C26) -> 4.4958025
A28: 24 | B28: 63 | C28: 4.824328 | D28: 0.021049147
B29: 67 | C29: 4.1038373 | D29: 0.018351033
B30: 88 | C30: 4.045167 | D30: 0.010901527
B31: 92 | C31: 5.1007059 | D31: 0.017906478
B32: AVERAGE | C32: =AVERAGE(C28:C31) -> 4.5185096
A33: 26 | B33: 59 | C33: 4.8603508 | D33: 0.05301883
B34: 61 | C34: 4.9682208 | D34: 0.014070932
B35: 84 | C35: 4.0153259 | D35: 0.02571563
B36: AVERAGE | C36: =AVERAGE(C33:C35) -> 4.6146325
A37: 28 | B37: 8 | C37: 4.1715902 | D37: 0.037808325
B38: 33 | C38: 4.4122907 | D38: 0.019374126
B39: 35 | C39: 4.3408062 | D39: 0.045095185
B40: AVERAGE | C40: =AVERAGE(C37:C39) -> 4.308229

Sheet Slot 9 - dose
A1: WAFER ID | B1: Platform | D1: Reticle title | E1: Slot | F1: Wavelength | G1: Wg length
E2: 16
A4: No | B4: Waveguide | C4: Type | D4: Chip | E4: Propagation loss (dB/cm) | F4: MSE | G4: Date | H4: Status | I4: Comment | J4: Further action
A5: 1 | B5: Straight | D5: 8 | E5: 5.07458 | F5: 0.073553706 | G5: 45814
A6: 2 | D6: 12 | E6: 6.5335165 | F6: 0.11794926
A7: 3 | D7: 16 | E7: 6.4670294 | F7: 0.14462367
A8: 4 | D8: 33 | E8: 5.4699514 | F8: 0.033209713
A9: 5 | D9: 35 | E9: 8.1883549 | F9: 0.025388064 | I9: wg4wg5 - fixed
A10: 6 | D10: 37 | E10: 8.2590304 | F10: 0.032314371 | I10: wg5wg6-fixed
A11: 7 | D11: 41 | E11: 5.6527211 | F11: 0.010069242 | I11: wg6-fixed
A12: 8 | D12: 59 | E12: 5.834152 | F12: 0.047173572
A13: 9 | D13: 61 | E13: 6.307685 | F13: 0.040265528
A14: 10 | D14: 63 | E14: 6.7060732 | F14: 0.026897711 | I14: wg6-fixed
A15: 11 | D15: 67 | E15: 5.0219386 | F15: 0.0086031721
A16: 12 | D16: 84 | E16: 5.4878183 | F16: 0.031711574
A17: 13 | D17: 88 | E17: 5.7520253 | F17: 0.025185997
A18: 14 | D18: 92 | E18: 14.242886 | F18: 1.1762175 | I18: NOT VALID
A22: Dose (mJ) | B22: Chip | C22: Loss (dB/cm) | D22: MSE
A23: 22 | B23: 12 | C23: 6.5335165 | D23: 0.11794926
B24: 16 | C24: 6.4670294 | D24: 0.14462367
B25: 37 | C25: 8.2590304 | D25: 0.032314371
B26: 41 | C26: 5.6527211 | D26: 0.010069242
B27: AVERAGE | C27: =AVERAGE(C23:C26) -> 6.7280744
A28: 24 | B28: 63 | C28: 6.7060732 | D28: 0.026897711
B29: 67 | C29: 5.0219386 | D29: 0.0086031721
B30: 88 | C30: 5.7520253 | D30: 0.025185997
B32: AVERAGE | C32: =AVERAGE(C28:C31) -> 5.826679
A33: 26 | B33: 59 | C33: 5.834152 | D33: 0.047173572
B34: 61 | C34: 6.307685 | D34: 0.040265528
B35: 84 | C35: 5.4878183 | D35: 0.031711574
B36: AVERAGE | C36: =AVERAGE(C33:C35) -> 5.8765518
A37: 28 | B37: 8 | C37: 5.07458 | D37: 0.073553706
B38: 33 | C38: 5.4699514 | D38: 0.033209713
B39: 35 | C39: 8.1883549 | D39: 0.025388064
B40: AVERAGE | C40: =AVERAGE(C37:C39) -> 6.2442954

Sheet SUMMARY - LOSS
S2: Different reticle , 698
A3: SLOT | B3: 5 | E3: 7 | H3: 9 | K3: 11 | N3: 16 | Q3: 12 | T3: 15
A4: Dose (mJ) | B4: Chip | C4: Loss (dB/cm) | D4: MSE | E4: Chip | F4: Loss (dB/cm) | G4: MSE | H4: Chip | I4: Loss (dB/cm) | J4: MSE | K4: Chip | L4: Loss (dB/cm) | M4: MSE | N4: Chip | O4: Loss (dB/cm) | P4: MSE | Q4: Chip | R4: Loss (dB/cm) | S4: MSE | T4: Chip | U4: Loss (dB/cm) | V4: MSE
A5: 22 | B5: 12 | C5: 8.6189027 | D5: 0.068842848 | E5: 12 | F5: 4.5594944 | G5: 0.082247904 | H5: 12 | I5: 6.5335165 | J5: 0.11794926 | K5: 37 | L5: 5.6724267 | M5: 0.013169828 | N5: 12 | O5: 3.9908181 | P5: 0.049396966 | Q5: 24 | R5: 7.0545807 | S5: 0.20910891 | T5: 24 | U5: 7.4253167 | V5: 0.057048755
B6: 16 | C6: 8.1633819 | D6: 0.051931011 | E6: 16 | F6: 4.5676045 | G6: 0.031333235 | H6: 16 | I6: 6.4670294 | J6: 0.14462367 | K6: - | L6: - | M6: - | N6: 16 | O6: 4.1715902 | P6: 0.037808325 | Q6: 36 | R6: 7.559376 | S6: 0.33270249 | T6: - | U6: - | V6: -
B7: 37 | C7: 8.4013352 | D7: 0.13407392 | E7: - | F7: - | G7: - | H7: 37 | I7: 8.2590304 | J7: 0.032314371 | K7: - | L7: - | M7: - | N7: 37 | O7: 5.0957503 | P7: 0.028705435 | Q7: - | R7: - | S7: - | T7: - | U7: - | V7: -
B8: 41 | C8: 8.002845 | D8: 0.036268594 | E8: 41 | F8: 4.7918199 | G8: 0.018803199 | H8: 41 | I8: 5.6527211 | J8: 0.010069242 | K8: - | L8: - | M8: - | N8: 41 | O8: 4.7250513 | P8: 0.014534886 | Q8: 39 | R8: 6.8878792 | S8: 0.022577854 | T8: 39 | U8: 7.2038043 | V8: 0.06626441
B9: AVERAGE | C9: =AVERAGE(C5:C8) -> 8.2966162 | E9: AVERAGE | F9: =AVERAGE(F5:F8) -> 4.6396396 | H9: AVERAGE | I9: =AVERAGE(I5:I8) -> 6.7280744 | K9: AVERAGE | L9: =AVERAGE(L5:L5) -> 5.6724267 | N9: AVERAGE | O9: =AVERAGE(O5:O8) -> 4.4958025 | Q9: AVERAGE | R9: =AVERAGE(R5:R8) -> 7.1672786 | T9: AVERAGE | U9: =AVERAGE(U5:U6) -> 7.4253167
A10: 24 | B10: 63 | C10: 6.7016685 | D10: 0.042181949 | E10: 63 | F10: 5.4052016 | G10: 0.011621006 | H10: 63 | I10: 6.7060732 | J10: 0.026897711 | K10: 54 | L10: 4.5212136 | M10: 0.0078438196 | N10: 63 | O10: 4.824328 | P10: 0.021049147 | Q10: 51 | R10: 6.2792691 | S10: 0.016077686 | T10: 51 | U10: 7.7869172 | V10: 0.008394457
B11: 67 | C11: 6.6207462 | D11: 0.075842604 | E11: 65 | F11: 4.6602055 | G11: 0.069539105 | H11: 67 | I11: 5.0219386 | J11: 0.0086031721 | K11: 76 | L11: 5.1447723 | M11: 0.018529104 | N11: 67 | O11: 4.1038373 | P11: 0.018351033 | Q11: 54 | R11: 3.4768161 | S11: 0.006000173 | T11: 54 | U11: 6.2923482 | V11: 0.005710118
B12: 88 | C12: 6.4793118 | D12: 0.065128094 | E12: 88 | F12: 4.050786 | G12: 0.027279707 | H12: 88 | I12: 5.7520253 | J12: 0.025185997 | K12: 89 | L12: 4.4133392 | M12: 0.015171549 | N12: 88 | O12: 4.045167 | P12: 0.010901527 | Q12: 63 | R12: 5.2923086 | S12: 0.072220967 | T12: 63 | U12: 7.2757576 | V12: 0.059220969
B13: 92 | C13: 8.6975148 | D13: 0.15427714 | E13: 92 | F13: 4.7759515 | G13: 0.0067731695 | K13: - | L13: - | M13: - | N13: 92 | O13: 5.1007059 | P13: 0.017906478 | Q13: 78 | R13: 4.0410067 | S13: 0.014557971 | T13: 78 | U13: 5.2635112 | V13: 0.011641517
B14: AVERAGE | C14: =AVERAGE(C10:C13) -> 7.1248103 | E14: AVERAGE | F14: =AVERAGE(F10:F13) -> 4.7230361 | H14: AVERAGE | I14: =AVERAGE(I10:I13) -> 5.826679 | K14: AVERAGE | L14: =AVERAGE(L10:L12) -> 4.6931084 | N14: AVERAGE | O14: =AVERAGE(O10:O13) -> 4.5185096 | Q14: AVERAGE | R14: =AVERAGE(R10:R13) -> 4.7723501 | T14: AVERAGE | U14: =AVERAGE(U10:U13) -> 6.6546335
A15: 26 | B15: 59 | C15: 5.7121413 | D15: 0.020440519 | E15: 59 | F15: 4.6096069 | G15: 0.054239011 | H15: 59 | I15: 5.834152 | J15: 0.047173572 | K15: 58 | L15: 4.932193 | M15: 0.026034511 | N15: 59 | O15: 4.8603508 | P15: 0.05301883 | Q15: 72 | R15: 3.8239438 | S15: 0.056732106 | T15: 72 | U15: 4.1770588 | V15: 0.001844966
B16: 61 | C16: 5.7012177 | D16: 0.067994551 | E16: - | F16: - | G16: - | H16: 61 | I16: 6.307685 | J16: 0.040265528 | K16: - | L16: - | M16: - | N16: 61 | O16: 4.9682208 | P16: 0.014070932 | Q16: - | R16: - | S16: - | T16: - | U16: - | V16: -
B17: 84 | C17: 5.5739141 | D17: 0.060228034 | E17: - | F17: - | G17: - | H17: 84 | I17: 5.4878183 | J17: 0.031711574 | K17: - | L17: - | M17: - | N17: 84 | O17: 4.0153259 | P17: 0.02571563 | Q17: - | R17: - | S17: - | T17: - | U17: - | V17: -
B18: AVERAGE | C18: =AVERAGE(C15:C17) -> 5.6624244 | E18: AVERAGE | F18: =AVERAGE(F15:F15) -> 4.6096069 | H18: AVERAGE | I18: =AVERAGE(I15:I17) -> 5.8765518 | K18: AVERAGE | L18: =AVERAGE(L15:L15) -> 4.932193 | N18: AVERAGE | O18: =AVERAGE(O15:O17) -> 4.6146325 | Q18: AVERAGE | R18: =AVERAGE(R15:R15) -> 3.8239438 | T18: AVERAGE | U18: =AVERAGE(U15:U15) -> 4.1770588
A19: 28 | B19: 8 | C19: 5.3469286 | D19: 0.03059289 | E19: 8 | F19: 3.8016985 | G19: 0.065715203 | H19: 8 | I19: 5.07458 | J19: 0.073553706 | K19: 1 | L19: 4.7761623 | M19: 2.4443262 | N19: 8 | O19: 4.1715902 | P19: 0.037808325 | Q19: 10 | R19: 3.0386561 | S19: 0.029479292 | T19: 10 | U19: 3.5427982 | V19: 0.0428601
B20: 33 | C20: 4.795825 | D20: 0.033622595 | E20: 33 | F20: 3.9804323 | G20: 0.028292244 | H20: 33 | I20: 5.4699514 | J20: 0.033209713 | K20: 33 | L20: 4.9059561 | M20: 0.045757777 | N20: 33 | O20: 4.4122907 | P20: 0.019374126 | Q20: 48 | R20: 4.9315566 | S20: 0.016351369 | T20: 48 | U20: 6.1933853 | V20: 0.000465079
B21: 35 | C21: 5.2665889 | D21: 0.014916907 | E21: 35 | F21: 4.9293885 | G21: 0.03434945 | H21: 35 | I21: 8.1883549 | J21: 0.025388064 | K21: 35 | L21: 5.0255103 | M21: 0.028879588 | N21: 35 | O21: 4.3408062 | P21: 0.045095185 | Q21: - | R21: - | S21: - | T21: - | U21: - | V21: -
B22: - | C22: - | D22: - | E22: - | F22: - | G22: - | K22: 47 | L22: 5.0594241 | M22: 0.026731825 | N22: - | O22: - | P22: - | Q22: - | R22: - | S22: - | T22: - | U22: - | V22: -
B23: AVERAGE | C23: =AVERAGE(C19:C21) -> 5.1364475 | E23: AVERAGE | F23: =AVERAGE(F19:F21) -> 4.2371731 | H23: AVERAGE | I23: =AVERAGE(I19:I22) -> 6.2442954 | K23: AVERAGE | L23: =AVERAGE(L19:L22) -> 4.9417632 | N23: AVERAGE | O23: =AVERAGE(O19:O21) -> 4.308229 | Q23: AVERAGE | R23: =AVERAGE(R19:R20) -> 3.9851063 | T23: AVERAGE | U23: =AVERAGE(U19:U20) -> 4.8680917

Sheet WAFERMAP - Dose Study _slots
C1: SLOT 5 | AA1: SLOT 5
F2: 0 | G2: 1 | H2: 2 | I2: 3 | J2: 4 | K2: 5 | L2: 6 | M2: 7 | N2: 8 | O2: 9 | P2: 10 | Q2: 11 | R2: 12 | S2: 13 | T2: 14 | AD2: 0 | AE2: 1 | AF2: 2 | AG2: 3 | AH2: 4 | AI2: 5 | AJ2: 6 | AK2: 7 | AL2: 8 | AM2: 9 | AN2: 10 | AO2: 11 | AP2: 12 | AQ2: 13 | AR2: 14
F3: -7 | G3: -6 | H3: -5 | I3: -4 | J3: -3 | K3: -2 | L3: -1 | M3: 0 | N3: 1 | O3: 2 | P3: 3 | Q3: 4 | R3: 5 | S3: 6 | T3: 7 | AD3: -7 | AE3: -6 | AF3: -5 | AG3: -4 | AH3: -3 | AI3: -2 | AJ3: -1 | AK3: 0 | AL3: 1 | AM3: 2 | AN3: 3 | AO3: 4 | AP3: 5 | AQ3: 6 | AR3: 7
D4: 10 | E4: 5 | AB4: 10 | AC4: 5
D5: 9 | E5: 4 | L5: 1 | M5: 2 | N5: 3 | O5: 4 | AB5: 9 | AC5: 4
D6: 8 | E6: 3 | J6: 8 | K6: 9 | L6: 10 | M6: 11 | N6: 12 | O6: 13 | P6: 14 | Q6: 15 | R6: 16 | AB6: 8 | AC6: 3 | AH6: ='Slot 5 - dose'!C37 -> 5.3469286 | AL6: ='Slot 5 - dose'!C23 -> 8.6189027 | AP6: ='Slot 5 - dose'!C24 -> 8.1633819
D7: 7 | E7: 2 | I7: 19 | J7: 20 | K7: 21 | L7: 22 | M7: 23 | N7: 24 | O7: 25 | P7: 26 | Q7: 27 | R7: 28 | X7: 22mJ | AB7: 7 | AC7: 2 | AV7: 22mJ
D8: 6 | E8: 1 | I8: 32 | J8: 33 | K8: 34 | L8: 35 | M8: 36 | N8: 37 | O8: 38 | P8: 39 | Q8: 40 | R8: 41 | X8: 24mJ | AB8: 6 | AC8: 1 | AH8: ='Slot 5 - dose'!C38 -> 4.795825 | AJ8: ='Slot 5 - dose'!C39 -> 5.2665889 | AL8: ='Slot 5 - dose'!C25 -> 8.4013352 | AP8: ='Slot 5 - dose'!C26 -> 8.002845 | AV8: 24mJ
D9: 5 | E9: 0 | I9: 45 | J9: 46 | K9: 47 | L9: 48 | M9: 49 | N9: 50 | O9: 51 | P9: 52 | Q9: 53 | R9: 54 | X9: 26mJ | AB9: 5 | AC9: 0 | AV9: 26mJ
D10: 4 | E10: -1 | I10: 58 | J10: 59 | K10: 60 | L10: 61 | M10: 62 | N10: 63 | O10: 64 | P10: 65 | Q10: 66 | R10: 67 | X10: 28mJ | AB10: 4 | AC10: -1 | AH10: ='Slot 5 - dose'!C33 -> 5.7121413 | AJ10: ='Slot 5 - dose'!C34 -> 5.7012177 | AL10: ='Slot 5 - dose'!C28 -> 6.7016685 | AP10: ='Slot 5 - dose'!C29 -> 6.6207462 | AV10: 28mJ
D11: 3 | E11: -2 | I11: 71 | J11: 72 | K11: 73 | L11: 74 | M11: 75 | N11: 76 | O11: 77 | P11: 78 | Q11: 79 | R11: 80 | X11: CENTRE | AB11: 3 | AC11: -2 | AV11: CENTRE
D12: 2 | E12: -3 | J12: 84 | K12: 85 | L12: 86 | M12: 87 | N12: 88 | O12: 89 | P12: 90 | Q12: 91 | R12: 92 | W12: M | X12: MEASURED | AB12: 2 | AC12: -3 | AH12: ='Slot 5 - dose'!C35 -> 5.5739141 | AL12: ='Slot 5 - dose'!C30 -> 6.4793118 | AP12: ='Slot 5 - dose'!C31 -> 8.6975148
D13: 1 | E13: -4 | L13: 95 | M13: 96 | N13: 97 | O13: 98 | AB13: 1 | AC13: -4
D14: 0 | E14: -5 | AB14: 0 | AC14: -5
C17: SLOT 7 | AA17: SLOT 7
F18: 0 | G18: 1 | H18: 2 | I18: 3 | J18: 4 | K18: 5 | L18: 6 | M18: 7 | N18: 8 | O18: 9 | P18: 10 | Q18: 11 | R18: 12 | S18: 13 | T18: 14 | AD18: 0 | AE18: 1 | AF18: 2 | AG18: 3 | AH18: 4 | AI18: 5 | AJ18: 6 | AK18: 7 | AL18: 8 | AM18: 9 | AN18: 10 | AO18: 11 | AP18: 12 | AQ18: 13 | AR18: 14
F19: -7 | G19: -6 | H19: -5 | I19: -4 | J19: -3 | K19: -2 | L19: -1 | M19: 0 | N19: 1 | O19: 2 | P19: 3 | Q19: 4 | R19: 5 | S19: 6 | T19: 7 | AD19: -7 | AE19: -6 | AF19: -5 | AG19: -4 | AH19: -3 | AI19: -2 | AJ19: -1 | AK19: 0 | AL19: 1 | AM19: 2 | AN19: 3 | AO19: 4 | AP19: 5 | AQ19: 6 | AR19: 7
D20: 10 | E20: 5 | AB20: 10 | AC20: 5
D21: 9 | E21: 4 | L21: 1 | M21: 2 | N21: 3 | O21: 4 | AB21: 9 | AC21: 4
D22: 8 | E22: 3 | J22: 8 | K22: 9 | L22: 10 | M22: 11 | N22: 12 | O22: 13 | P22: 14 | Q22: 15 | R22: 16 | AB22: 8 | AC22: 3 | AH22: ='Slot 7 - dose'!C35 -> 3.8016985 | AL22: ='Slot 7 - dose'!C23 -> 4.5594944 | AP22: ='Slot 7 - dose'!C24 -> 4.5676045
D23: 7 | E23: 2 | I23: 19 | J23: 20 | K23: 21 | L23: 22 | M23: 23 | N23: 24 | O23: 25 | P23: 26 | Q23: 27 | R23: 28 | X23: 22mJ | AB23: 7 | AC23: 2 | AV23: 22mJ
D24: 6 | E24: 1 | I24: 32 | J24: 33 | K24: 34 | L24: 35 | M24: 36 | N24: 37 | O24: 38 | P24: 39 | Q24: 40 | R24: 41 | X24: 24mJ | AB24: 6 | AC24: 1 | AH24: ='Slot 7 - dose'!C36 -> 3.9804323 | AJ24: ='Slot 7 - dose'!C37 -> 4.9293885 | AP24: ='Slot 7 - dose'!C25 -> 4.7918199 | AV24: 24mJ
D25: 5 | E25: 0 | I25: 45 | J25: 46 | K25: 47 | L25: 48 | M25: 49 | N25: 50 | O25: 51 | P25: 52 | Q25: 53 | R25: 54 | X25: 26mJ | AB25: 5 | AC25: 0 | AV25: 26mJ
D26: 4 | E26: -1 | I26: 58 | J26: 59 | K26: 60 | L26: 61 | M26: 62 | N26: 63 | O26: 64 | P26: 65 | Q26: 66 | R26: 67 | X26: 28mJ | AB26: 4 | AC26: -1 | AH26: ='Slot 7 - dose'!C32 -> 4.6096069 | AL26: ='Slot 7 - dose'!C27 -> 5.4052016 | AN26: ='Slot 7 - dose'!C28 -> 4.6602055 | AV26: 28mJ
D27: 3 | E27: -2 | I27: 71 | J27: 72 | K27: 73 | L27: 74 | M27: 75 | N27: 76 | O27: 77 | P27: 78 | Q27: 79 | R27: 80 | X27: CENTRE | AB27: 3 | AC27: -2 | AV27: CENTRE
D28: 2 | E28: -3 | J28: 84 | K28: 85 | L28: 86 | M28: 87 | N28: 88 | O28: 89 | P28: 90 | Q28: 91 | R28: 92 | W28: M | X28: MEASURED | AB28: 2 | AC28: -3 | AL28: ='Slot 7 - dose'!C29 -> 4.050786 | AP28: ='Slot 7 - dose'!C30 -> 4.7759515
D29: 1 | E29: -4 | L29: 95 | M29: 96 | N29: 97 | O29: 98 | AB29: 1 | AC29: -4
D30: 0 | E30: -5 | AB30: 0 | AC30: -5
C33: SLOT 11 | AA33: SLOT 11
F34: 0 | G34: 1 | H34: 2 | I34: 3 | J34: 4 | K34: 5 | L34: 6 | M34: 7 | N34: 8 | O34: 9 | P34: 10 | Q34: 11 | R34: 12 | S34: 13 | T34: 14 | AD34: 0 | AE34: 1 | AF34: 2 | AG34: 3 | AH34: 4 | AI34: 5 | AJ34: 6 | AK34: 7 | AL34: 8 | AM34: 9 | AN34: 10 | AO34: 11 | AP34: 12 | AQ34: 13 | AR34: 14
F35: -7 | G35: -6 | H35: -5 | I35: -4 | J35: -3 | K35: -2 | L35: -1 | M35: 0 | N35: 1 | O35: 2 | P35: 3 | Q35: 4 | R35: 5 | S35: 6 | T35: 7 | AD35: -7 | AE35: -6 | AF35: -5 | AG35: -4 | AH35: -3 | AI35: -2 | AJ35: -1 | AK35: 0 | AL35: 1 | AM35: 2 | AN35: 3 | AO35: 4 | AP35: 5 | AQ35: 6 | AR35: 7
D36: 10 | E36: 5 | AB36: 10 | AC36: 5
D37: 9 | E37: 4 | L37: 1 | M37: 2 | N37: 3 | O37: 4 | AB37: 9 | AC37: 4 | AJ37: ='Slot 11 - dose'!C31 -> 4.7761623
D38: 8 | E38: 3 | J38: 8 | K38: 9 | L38: 10 | M38: 11 | N38: 12 | O38: 13 | P38: 14 | Q38: 15 | R38: 16 | AB38: 8 | AC38: 3
D39: 7 | E39: 2 | I39: 19 | J39: 20 | K39: 21 | L39: 22 | M39: 23 | N39: 24 | O39: 25 | P39: 26 | Q39: 27 | R39: 28 | X39: 22mJ | AB39: 7 | AC39: 2 | AV39: 22mJ
D40: 6 | E40: 1 | I40: 32 | J40: 33 | K40: 34 | L40: 35 | M40: 36 | N40: 37 | O40: 38 | P40: 39 | Q40: 40 | R40: 41 | X40: 24mJ | AB40: 6 | AC40: 1 | AH40: ='Slot 11 - dose'!C32 -> 4.9059561 | AJ40: ='Slot 11 - dose'!C33 -> 5.0255103 | AL40: ='Slot 11 - dose'!C23 -> 5.6724267 | AV40: 24mJ
D41: 5 | E41: 0 | I41: 45 | J41: 46 | K41: 47 | L41: 48 | M41: 49 | N41: 50 | O41: 51 | P41: 52 | Q41: 53 | R41: 54 | X41: 26mJ | AB41: 5 | AC41: 0 | AI41: ='Slot 11 - dose'!C34 -> 5.0594241 | AP41: ='Slot 11 - dose'!C25 -> 4.5212136 | AV41: 26mJ
D42: 4 | E42: -1 | I42: 58 | J42: 59 | K42: 60 | L42: 61 | M42: 62 | N42: 63 | O42: 64 | P42: 65 | Q42: 66 | R42: 67 | X42: 28mJ | AB42: 4 | AC42: -1 | AG42: ='Slot 11 - dose'!C29 -> 4.932193 | AV42: 28mJ
D43: 3 | E43: -2 | I43: 71 | J43: 72 | K43: 73 | L43: 74 | M43: 75 | N43: 76 | O43: 77 | P43: 78 | Q43: 79 | R43: 80 | X43: CENTRE | AB43: 3 | AC43: -2 | AL43: ='Slot 11 - dose'!C26 -> 5.1447723 | AV43: CENTRE
D44: 2 | E44: -3 | J44: 84 | K44: 85 | L44: 86 | M44: 87 | N44: 88 | O44: 89 | P44: 90 | Q44: 91 | R44: 92 | W44: M | X44: MEASURED | AB44: 2 | AC44: -3 | AM44: ='Slot 11 - dose'!C27 -> 4.4133392
...

Sheet Wafermap - Dose Study -referenc
S1: MPW40slot1 | W1: SLOT 1 | Y1: RIB WGs
F2: 1 | G2: 2 | H2: 3 | I2: 4 | J2: 5 | K2: 6 | L2: 7 | AO2: 1 | AP2: 2 | AQ2: 3 | AR2: 4 | AS2: 5 | AT2: 6 | AU2: 7
D3: 8 | E3: 9 | F3: 10 | G3: 11 | H3: 12 | I3: 13 | J3: 14 | K3: 15 | L3: 16 | M3: 17 | N3: 18 | AM3: 8 | AN3: 9 | AO3: 10 | AP3: 11 | AQ3: 12 | AR3: 13 | AS3: 14 | AT3: 15 | AU3: 16 | AV3: 17 | AW3: 18
C4: 19 | D4: 20 | E4: 21 | F4: 22 | G4: 23 | H4: 24 | I4: 25 | J4: 26 | K4: 27 | L4: 28 | M4: 29 | N4: 30 | O4: 31 | AL4: 19 | AM4: 20 | AN4: 21 | AO4: 22 | AP4: 23 | AQ4: 24 | AR4: 25 | AS4: 26 | AT4: 27 | AU4: 28 | AV4: 29 | AW4: 30 | AX4: 31
C5: 32 | D5: 33 | E5: 34 | F5: 35 | G5: 36 | H5: 37 | I5: 38 | J5: 39 | K5: 40 | L5: 41 | M5: 42 | N5: 43 | O5: 44 | AL5: 32 | AM5: 33 | AN5: 34 | AO5: 35 | AP5: 36 | AQ5: 37 | AR5: 38 | AS5: 39 | AT5: 40 | AU5: 41 | AV5: 42 | AW5: 43 | AX5: 44
C6: 45 | D6: 46 | E6: 47 | F6: 48 | G6: 49 | H6: 50 | I6: 51 | J6: 52 | K6: 53 | L6: 54 | M6: 55 | N6: 56 | O6: 57 | AL6: 45 | AM6: 46 | AN6: 47 | AO6: 48 | AP6: 49 | AQ6: 50 | AR6: 51 | AS6: 52 | AT6: 53 | AU6: 54 | AV6: 55 | AW6: 56 | AX6: 57
C7: 58 | D7: 59 | E7: 60 | F7: 61 | G7: 62 | H7: 63 | I7: 64 | J7: 65 | K7: 66 | L7: 67 | M7: 68 | N7: 69 | O7: 70 | AL7: 58 | AM7: 59 | AN7: 60 | AO7: 61 | AP7: 62 | AQ7: 63 | AR7: 64 | AS7: 65 | AT7: 66 | AU7: 67 | AV7: 68 | AW7: 69 | AX7: 70
C8: 71 | D8: 72 | E8: 73 | F8: 74 | G8: 75 | H8: 76 | I8: 77 | J8: 78 | K8: 79 | L8: 80 | M8: 81 | N8: 82 | O8: 83 | AL8: 71 | AM8: 72 | AN8: 73 | AO8: 74 | AP8: 75 | AQ8: 76 | AR8: 77 | AS8: 78 | AT8: 79 | AU8: 80 | AV8: 81 | AW8: 82 | AX8: 83
D9: 84 | E9: 85 | F9: 86 | G9: 87 | H9: 88 | I9: 89 | J9: 90 | K9: 91 | L9: 92 | M9: 93 | N9: 94 | AM9: 84 | AN9: 85 | AO9: 86 | AP9: 87 | AQ9: 88 | AR9: 89 | AS9: 90 | AT9: 91 | AU9: 92 | AV9: 93 | AW9: 94
F10: 95 | G10: 96 | H10: 97 | I10: 98 | J10: 99 | K10: 100 | L10: 101 | AO10: 95 | AP10: 96 | AQ10: 97 | AR10: 98 | AS10: 99 | AT10: 100 | AU10: 101
F13: 0 | G13: 1 | H13: 2 | I13: 3 | J13: 4 | K13: 5 | L13: 6 | M13: 7 | N13: 8 | O13: 9 | P13: 10 | Q13: 11 | R13: 12 | S13: 13 | T13: 14 | X13: 0 | Y13: 1 | Z13: 2 | AA13: 3 | AB13: 4 | AC13: 5 | AD13: 6 | AE13: 7 | AF13: 8 | AG13: 9 | AH13: 10 | AI13: 11 | AJ13: 12 | AK13: 13 | AL13: 14 | AV13: 0 | AW13: 1 | AX13: 2 | AY13: 3 | AZ13: 4 | BA13: 5 | BB13: 6 | BC13: 7 | BD13: 8 | BE13: 9 | BF13: 10 | BG13: 11 | BH13: 12 | BI13: 13 | BJ13: 14 | BS13: 0 | BT13: 1 | BU13: 2 | BV13: 3 | BW13: 4 | BX13: 5 | BY13: 6 | BZ13: 7 | CA13: 8 | CB13: 9 | CC13: 10 | CD13: 11 | CE13: 12 | CF13: 13 | CG13: 14 | CO13: 0 | CP13: 1 | CQ13: 2 | CR13: 3 | CS13: 4 | CT13: 5 | CU13: 6 | CV13: 7 | CW13: 8 | CX13: 9 | CY13: 10 | CZ13: 11 | DA13: 12 | DB13: 13 | DC13: 14
F14: -7 | G14: -6 | H14: -5 | I14: -4 | J14: -3 | K14: -2 | L14: -1 | M14: 0 | N14: 1 | O14: 2 | P14: 3 | Q14: 4 | R14: 5 | S14: 6 | T14: 7 | X14: -7 | Y14: -6 | Z14: -5 | AA14: -4 | AB14: -3 | AC14: -2 | AD14: -1 | AE14: 0 | AF14: 1 | AG14: 2 | AH14: 3 | AI14: 4 | AJ14: 5 | AK14: 6 | AL14: 7 | AV14: -7 | AW14: -6 | AX14: -5 | AY14: -4 | AZ14: -3 | BA14: -2 | BB14: -1 | BC14: 0 | BD14: 1 | BE14: 2 | BF14: 3 | BG14: 4 | BH14: 5 | BI14: 6 | BJ14: 7 | BS14: -7 | BT14: -6 | BU14: -5 | BV14: -4 | BW14: -3 | BX14: -2 | BY14: -1 | BZ14: 0 | CA14: 1 | CB14: 2 | CC14: 3 | CD14: 4 | CE14: 5 | CF14: 6 | CG14: 7 | CO14: -7 | CP14: -6 | CQ14: -5 | CR14: -4 | CS14: -3 | CT14: -2 | CU14: -1 | CV14: 0 | CW14: 1 | CX14: 2 | CY14: 3 | CZ14: 4 | DA14: 5 | DB14: 6 | DC14: 7
D15: 10 | E15: 5 | V15: 10 | W15: 5 | AT15: 10 | AU15: 5 | BQ15: 10 | BR15: 5 | CM15: 10 | CN15: 5
D16: 9 | E16: 4 | J16: 1 | K16: 2 | L16: 3 | M16: 4 | N16: 5 | O16: 6 | P16: 7 | V16: 9 | W16: 4 | AT16: 9 | AU16: 4 | BQ16: 9 | BR16: 4 | BZ16: 1 | CA16: 2 | CB16: 3 | CC16: 4 | CD16: 5 | CE16: 6 | CF16: 7 | CM16: 9 | CN16: 4 | CV16: 1 | CW16: 2 | CX16: 3 | CY16: 4
D17: 8 | E17: 3 | H17: 8 | I17: 9 | J17: 10 | K17: 11 | L17: 12 | M17: 13 | N17: 14 | O17: 15 | P17: 16 | Q17: 17 | R17: 18 | V17: 8 | W17: 3 | AT17: 8 | AU17: 3 | BQ17: 8 | BR17: 3 | BX17: 8 | BY17: 9 | BZ17: 10 | CA17: 11 | CB17: 12 | CC17: 13 | CD17: 14 | CE17: 15 | CF17: 16 | CG17: 17 | CH17: 18 | CM17: 8 | CN17: 3 | CT17: 8 | CU17: 9 | CV17: 10 | CW17: 11 | CX17: 12 | CY17: 13 | CZ17: 14 | DA17: 15
D18: 7 | E18: 2 | G18: 19 | H18: 20 | I18: 21 | J18: 22 | K18: 23 | L18: 24 | M18: 25 | N18: 26 | O18: 27 | P18: 28 | Q18: 29 | R18: 30 | S18: 31 | V18: 7 | W18: 2 | AP18: 14mJ | AT18: 7 | AU18: 2 | BQ18: 7 | BR18: 2 | BW18: 19 | BX18: 20 | BY18: 21 | BZ18: 22 | CA18: 23 | CB18: 24 | CC18: 25 | CD18: 26 | CE18: 27 | CF18: 28 | CG18: 29 | CH18: 30 | CI18: 31 | CM18: 7 | CN18: 2 | CS18: 19 | CT18: 20 | CU18: 21 | CV18: 22 | CW18: 23 | CX18: 24 | CY18: 25 | CZ18: 26 | DA18: 27 | DB18: 28
D19: 6 | E19: 1 | G19: 32 | H19: 33 | I19: 34 | J19: 35 | K19: 36 | L19: 37 | M19: 38 | N19: 39 | O19: 40 | P19: 41 | Q19: 42 | R19: 43 | S19: 44 | V19: 6 | W19: 1 | AP19: 17mJ | AT19: 6 | AU19: 1 | BQ19: 6 | BR19: 1 | BW19: 32 | BX19: 33 | BY19: 34 | BZ19: 35 | CA19: 36 | CB19: 37 | CC19: 38 | CD19: 39 | CE19: 40 | CF19: 41 | CG19: 42 | CH19: 43 | CI19: 44 | CM19: 6 | CN19: 1 | CS19: 32 | CT19: 33 | CU19: 34 | CV19: 35 | CW19: 36 | CX19: 37 | CY19: 38 | CZ19: 39 | DA19: 40 | DB19: 41
D20: 5 | E20: 0 | G20: 45 | H20: 46 | I20: 47 | J20: 48 | K20: 49 | L20: 50 | M20: 51 | N20: 52 | O20: 53 | P20: 54 | Q20: 55 | R20: 56 | S20: 57 | V20: 5 | W20: 0 | AB20: 48 | AC20: 49 | AD20: 50 | AE20: X | AP20: 20mJ | AT20: 5 | AU20: 0 | BE20: X | BF20: 49 | BG20: 50 | BQ20: 5 | BR20: 0 | BW20: 45 | BX20: 46 | BY20: 47 | BZ20: 48 | CA20: 49 | CB20: 50 | CC20: 51 | CD20: 52 | CE20: 53 | CF20: 54 | CM20: 5 | CN20: 0 | CS20: 45 | CT20: 46 | CU20: 47 | CV20: 48 | CW20: 49 | CX20: 50 | CY20: 51 | CZ20: 52 | DA20: 53 | DB20: 54
D21: 4 | E21: -1 | G21: 58 | H21: 59 | I21: 60 | J21: 61 | K21: 62 | L21: 63 | M21: 64 | N21: 65 | O21: 66 | P21: 67 | Q21: 68 | R21: 69 | S21: 70 | V21: 4 | W21: -1 | AP21: 23mJ | AT21: 4 | AU21: -1 | BQ21: 4 | BR21: -1 | BW21: 58 | BX21: 59 | BY21: 60 | BZ21: 61 | CA21: 62 | CB21: 63 | CC21: 64 | CD21: 65 | CE21: 66 | CF21: 67 | CG21: 68 | CH21: 69 | CI21: 70 | CM21: 4 | CN21: -1 | CS21: 58 | CT21: 59 | CU21: 60 | CV21: 61 | CW21: 62 | CX21: 63 | CY21: 64 | CZ21: 65 | DA21: 66 | DB21: 67
D22: 3 | E22: -2 | G22: 71 | H22: 72 | I22: 73 | J22: 74 | K22: 75 | L22: 76 | M22: 77 | N22: 78 | O22: 79 | P22: 80 | Q22: 81 | R22: 82 | S22: 83 | V22: 3 | W22: -2 | AT22: 3 | AU22: -2 | BQ22: 3 | BR22: -2 | BW22: 71 | BX22: 72 | BY22: 73 | BZ22: 74 | CA22: 75 | CB22: 76 | CC22: 77 | CD22: 78 | CE22: 79 | CF22: 80 | CG22: 81 | CH22: 82 | CI22: 83 | CM22: 3 | CN22: -2 | CS22: 71 | CT22: 72 | CU22: 73 | CV22: 74 | CW22: 75 | CX22: 76 | CY22: 77 | CZ22: 78 | DA22: 79 | DB22: 80
D23: 2 | E23: -3 | H23: 84 | I23: 85 | J23: 86 | K23: 87 | L23: 88 | M23: 89 | N23: 90 | O23: 91 | P23: 92 | Q23: 93 | R23: 94 | V23: 2 | W23: -3 | AT23: 2 | AU23: -3 | BQ23: 2 | BR23: -3 | BX23: 84 | BY23: 85 | BZ23: 86 | CA23: 87 | CB23: 88 | CC23: 89 | CD23: 90 | CE23: 91 | CF23: 92 | CG23: 93 | CH23: 94 | CM23: 2 | CN23: -3 | CT23: 84 | CU23: 85 | CV23: 86 | CW23: 87 | CX23: 88 | CY23: 89 | CZ23: 90 | DA23: 91
D24: 1 | E24: -4 | J24: 95 | K24: 96 | L24: 97 | M24: 98 | N24: 99 | O24: 100 | P24: 101 | V24: 1 | W24: -4 | AT24: 1 | AU24: -4 | BQ24: 1 | BR24: -4 | BZ24: 95 | CA24: 96 | CB24: 97 | CC24: 98 | CD24: 99 | CE24: 100 | CF24: 101 | CM24: 1 | CN24: -4 | CV24: 95 | CW24: 96 | CX24: 97 | CY24: 98
D25: 0 | E25: -5 | V25: 0 | W25: -5 | AT25: 0 | AU25: -5 | BQ25: 0 | BR25: -5 | CM25: 0 | CN25: -5
BD27: 14mJ
BD28: 17mJ
BD29: 20mJ
BD30: 23mJ

Sheet MPW41 NEW- WaferMap Loss
J1: REFERENCE | AF1: SLOT 7 - Avg. Loss = 4.39 dB/cm | AZ1: SLOT 11 - Avg. Loss = 5.04 dB/cm | BT1: SLOT 12 - Avg. Loss = 4.72 dB/cm | CN1: SLOT 15 - Avg. Loss = 4.97 dB/cm
J2: Columns | AF2: Columns | AZ2: Columns | BT2: Columns | CN2: Columns
J3: 0 | K3: 1 | L3: 2 | M3: 3 | N3: 4 | O3: 5 | P3: 6 | Q3: 7 | R3: 8 | S3: 9 | T3: 10 | U3: 11 | V3: 12 | W3: 13 | X3: 14 | AF3: 0 | AG3: 1 | AH3: 2 | AI3: 3 | AJ3: 4 | AK3: 5 | AL3: 6 | AM3: 7 | AN3: 8 | AO3: 9 | AP3: 10 | AQ3: 11 | AR3: 12 | AS3: 13 | AT3: 14 | AZ3: 0 | BA3: 1 | BB3: 2 | BC3: 3 | BD3: 4 | BE3: 5 | BF3: 6 | BG3: 7 | BH3: 8 | BI3: 9 | BJ3: 10 | BK3: 11 | BL3: 12 | BM3: 13 | BN3: 14 | BT3: 0 | BU3: 1 | BV3: 2 | BW3: 3 | BX3: 4 | BY3: 5 | BZ3: 6 | CA3: 7 | CB3: 8 | CC3: 9 | CD3: 10 | CE3: 11 | CF3: 12 | CG3: 13 | CH3: 14 | CN3: 0 | CO3: 1 | CP3: 2 | CQ3: 3 | CR3: 4 | CS3: 5 | CT3: 6 | CU3: 7 | CV3: 8 | CW3: 9 | CX3: 10 | CY3: 11 | CZ3: 12 | DA3: 13 | DB3: 14
J4: -7 | K4: -6 | L4: -5 | M4: -4 | N4: -3 | O4: -2 | P4: -1 | Q4: 0 | R4: 1 | S4: 2 | T4: 3 | U4: 4 | V4: 5 | W4: 6 | X4: 7 | AF4: -7 | AG4: -6 | AH4: -5 | AI4: -4 | AJ4: -3 | AK4: -2 | AL4: -1 | AM4: 0 | AN4: 1 | AO4: 2 | AP4: 3 | AQ4: 4 | AR4: 5 | AS4: 6 | AT4: 7 | AZ4: -7 | BA4: -6 | BB4: -5 | BC4: -4 | BD4: -3 | BE4: -2 | BF4: -1 | BG4: 0 | BH4: 1 | BI4: 2 | BJ4: 3 | BK4: 4 | BL4: 5 | BM4: 6 | BN4: 7 | BT4: -7 | BU4: -6 | BV4: -5 | BW4: -4 | BX4: -3 | BY4: -2 | BZ4: -1 | CA4: 0 | CB4: 1 | CC4: 2 | CD4: 3 | CE4: 4 | CF4: 5 | CG4: 6 | CH4: 7 | CN4: -7 | CO4: -6 | CP4: -5 | CQ4: -4 | CR4: -3 | CS4: -2 | CT4: -1 | CU4: 0 | CV4: 1 | CW4: 2 | CX4: 3 | CY4: 4 | CZ4: 5 | DA4: 6 | DB4: 7
G5: Rows | H5: 10 | I5: 5 | AC5: Rows | AD5: 10 | AE5: 5 | AW5: Rows | AX5: 10 | AY5: 5 | BQ5: Rows | BR5: 10 | BS5: 5 | CK5: Rows | CL5: 10 | CM5: 5
H6: 9 | I6: 4 | Q6: 1 | R6: 2 | S6: 3 | T6: 4 | AD6: 9 | AE6: 4 | AX6: 9 | AY6: 4 | BR6: 9 | BS6: 4 | CL6: 9 | CM6: 4
H7: 8 | I7: 3 | O7: 8 | P7: 9 | Q7: 10 | R7: 11 | S7: 12 | T7: 13 | U7: 14 | V7: 15 | AD7: 8 | AE7: 3 | AK7: ='Slot 7 '!E5 -> 3.8016985 | AO7: ='Slot 7 '!E6 -> 4.5594944 | AX7: 8 | AY7: 3 | BR7: 8 | BS7: 3 | CA7: ='Slot 12'!E5 -> 3.0386561 | CL7: 8 | CM7: 3 | CU7: ='Slot 15'!E5 -> 3.5583071
H8: 7 | I8: 2 | N8: 19 | O8: 20 | P8: 21 | Q8: 22 | R8: 23 | S8: 24 | T8: 25 | U8: 26 | V8: 27 | W8: 28 | AD8: 7 | AE8: 2 | AX8: 7 | AY8: 2 | BR8: 7 | BS8: 2 | CL8: 7 | CM8: 2
H9: 6 | I9: 1 | N9: 32 | O9: 33 | P9: 34 | Q9: 35 | R9: 36 | S9: 37 | T9: 38 | U9: 39 | V9: 40 | W9: 41 | AD9: 6 | AE9: 1 | AK9: ='Slot 7 '!E8 -> 3.9804323 | AM9: ='Slot 7 '!E9 -> 4.9293885 | AS9: ='Slot 7 '!E11 -> 4.7918199 | AX9: 6 | AY9: 1 | BE9: ='Slot 11'!E6 -> 4.9059561 | BG9: ='Slot 11'!E7 -> 5.0255103 | BI9: ='Slot 11'!E8 -> 5.6724267 | BR9: 6 | BS9: 1 | CE9: ='Slot 12'!E8 -> 6.8878792 | CL9: 6 | CM9: 1
H10: 5 | I10: 0 | N10: 45 | O10: 46 | P10: 47 | Q10: 48 | R10: 49 | S10: 50 | T10: 51 | U10: 52 | V10: 53 | W10: 54 | AD10: 5 | AE10: 0 | AX10: 5 | AY10: 0 | BF10: ='Slot 11'!E9 -> 5.0594241 | BM10: ='Slot 11'!E10 -> 4.5212136 | BR10: 5 | BS10: 0 | CA10: ='Slot 12'!E9 -> 4.9315566 | CD10: ='Slot 12'!E10 -> 6.2792691 | CG10: ='Slot 12'!E11 -> 3.4768161 | CL10: 5 | CM10: 0 | CR10: ='Slot 15'!E9 -> 3.1316735 | CU10: ='Slot 15'!E10 -> 5.9847798 | DA10: ='Slot 15'!E12 -> 5.9680225
H11: 4 | I11: -1 | N11: 58 | O11: 59 | P11: 60 | Q11: 61 | R11: 62 | S11: 63 | T11: 64 | U11: 65 | V11: 66 | W11: 67 | AD11: 4 | AE11: -1 | AK11: ='Slot 7 '!E12 -> 4.6096069 | AX11: 4 | AY11: -1 | BD11: ='Slot 11'!E11 -> 4.932193 | BR11: 4 | BS11: -1 | CC11: ='Slot 12'!E12 -> 5.2923086 | CL11: 4 | CM11: -1 | CW11: ='Slot 15'!E13 -> 6.9911106
H12: 3 | I12: -2 | N12: 71 | O12: 72 | P12: 73 | Q12: 74 | R12: 75 | S12: 76 | T12: 77 | U12: 78 | V12: 79 | W12: 80 | AD12: 3 | AE12: -2 | AX12: 3 | AY12: -2 | BI12: ='Slot 11'!E12 -> 5.1447723 | BR12: 3 | BS12: -2 | BY12: ='Slot 12'!E13 -> 3.8239438 | CE12: ='Slot 12'!E14 -> 4.0410067 | CL12: 3 | CM12: -2 | CS12: ='Slot 15'!E14 -> 4.2805664 | CY12: ='Slot 15'!E15 -> 4.8450666
H13: 2 | I13: -3 | O13: 84 | P13: 85 | Q13: 86 | R13: 87 | S13: 88 | T13: 89 | U13: 90 | V13: 91 | AD13: 2 | AE13: -3 | AO13: ='Slot 7 '!E17 -> 4.050786 | AX13: 2 | AY13: -3 | BJ13: ='Slot 11'!E13 -> 4.4133392 | BR13: 2 | BS13: -3 | CL13: 2 | CM13: -3
H14: 1 | I14: -4 | Q14: 95 | R14: 96 | S14: 97 | T14: 98 | AD14: 1 | AE14: -4 | AX14: 1 | AY14: -4 | BR14: 1 | BS14: -4 | CL14: 1 | CM14: -4
H15: 0 | I15: -5 | AD15: 0 | AE15: -5 | AX15: 0 | AY15: -5 | BR15: 0 | BS15: -5 | CL15: 0 | CM15: -5

Sheet Wafermap - SLOT1
S1: MPW40slot1 | W1: SLOT 1 | Y1: RIB WGs
F2: 1 | G2: 2 | H2: 3 | I2: 4 | J2: 5 | K2: 6 | L2: 7 | AO2: 1 | AP2: 2 | AQ2: 3 | AR2: 4 | AS2: 5 | AT2: 6 | AU2: 7
D3: 8 | E3: 9 | F3: 10 | G3: 11 | H3: 12 | I3: 13 | J3: 14 | K3: 15 | L3: 16 | M3: 17 | N3: 18 | AM3: 8 | AN3: 9 | AO3: 10 | AP3: 11 | AQ3: 12 | AR3: 13 | AS3: 14 | AT3: 15 | AU3: 16 | AV3: 17 | AW3: 18
C4: 19 | D4: 20 | E4: 21 | F4: 22 | G4: 23 | H4: 24 | I4: 25 | J4: 26 | K4: 27 | L4: 28 | M4: 29 | N4: 30 | O4: 31 | AL4: 19 | AM4: 20 | AN4: 21 | AO4: 22 | AP4: 23 | AQ4: 24 | AR4: 25 | AS4: 26 | AT4: 27 | AU4: 28 | AV4: 29 | AW4: 30 | AX4: 31
C5: 32 | D5: 33 | E5: 34 | F5: 35 | G5: 36 | H5: 37 | I5: 38 | J5: 39 | K5: 40 | L5: 41 | M5: 42 | N5: 43 | O5: 44 | AL5: 32 | AM5: 33 | AN5: 34 | AO5: 35 | AP5: 36 | AQ5: 37 | AR5: 38 | AS5: 39 | AT5: 40 | AU5: 41 | AV5: 42 | AW5: 43 | AX5: 44
C6: 45 | D6: 46 | E6: 47 | F6: 48 | G6: 49 | H6: 50 | I6: 51 | J6: 52 | K6: 53 | L6: 54 | M6: 55 | N6: 56 | O6: 57 | AL6: 45 | AM6: 46 | AN6: 47 | AO6: 48 | AP6: 49 | AQ6: 50 | AR6: 51 | AS6: 52 | AT6: 53 | AU6: 54 | AV6: 55 | AW6: 56 | AX6: 57
C7: 58 | D7: 59 | E7: 60 | F7: 61 | G7: 62 | H7: 63 | I7: 64 | J7: 65 | K7: 66 | L7: 67 | M7: 68 | N7: 69 | O7: 70 | AL7: 58 | AM7: 59 | AN7: 60 | AO7: 61 | AP7: 62 | AQ7: 63 | AR7: 64 | AS7: 65 | AT7: 66 | AU7: 67 | AV7: 68 | AW7: 69 | AX7: 70
C8: 71 | D8: 72 | E8: 73 | F8: 74 | G8: 75 | H8: 76 | I8: 77 | J8: 78 | K8: 79 | L8: 80 | M8: 81 | N8: 82 | O8: 83 | AL8: 71 | AM8: 72 | AN8: 73 | AO8: 74 | AP8: 75 | AQ8: 76 | AR8: 77 | AS8: 78 | AT8: 79 | AU8: 80 | AV8: 81 | AW8: 82 | AX8: 83
D9: 84 | E9: 85 | F9: 86 | G9: 87 | H9: 88 | I9: 89 | J9: 90 | K9: 91 | L9: 92 | M9: 93 | N9: 94 | AM9: 84 | AN9: 85 | AO9: 86 | AP9: 87 | AQ9: 88 | AR9: 89 | AS9: 90 | AT9: 91 | AU9: 92 | AV9: 93 | AW9: 94
F10: 95 | G10: 96 | H10: 97 | I10: 98 | J10: 99 | K10: 100 | L10: 101 | AO10: 95 | AP10: 96 | AQ10: 97 | AR10: 98 | AS10: 99 | AT10: 100 | AU10: 101
F13: 0 | G13: 1 | H13: 2 | I13: 3 | J13: 4 | K13: 5 | L13: 6 | M13: 7 | N13: 8 | O13: 9 | P13: 10 | Q13: 11 | R13: 12 | S13: 13 | T13: 14 | X13: 0 | Y13: 1 | Z13: 2 | AA13: 3 | AB13: 4 | AC13: 5 | AD13: 6 | AE13: 7 | AF13: 8 | AG13: 9 | AH13: 10 | AI13: 11 | AJ13: 12 | AK13: 13 | AL13: 14
F14: -7 | G14: -6 | H14: -5 | I14: -4 | J14: -3 | K14: -2 | L14: -1 | M14: 0 | N14: 1 | O14: 2 | P14: 3 | Q14: 4 | R14: 5 | S14: 6 | T14: 7 | X14: -7 | Y14: -6 | Z14: -5 | AA14: -4 | AB14: -3 | AC14: -2 | AD14: -1 | AE14: 0 | AF14: 1 | AG14: 2 | AH14: 3 | AI14: 4 | AJ14: 5 | AK14: 6 | AL14: 7
D15: 10 | E15: 5 | V15: 10 | W15: 5
D16: 9 | E16: 4 | J16: 1 | K16: 2 | L16: 3 | M16: 4 | N16: 5 | O16: 6 | P16: 7 | V16: 9 | W16: 4
D17: 8 | E17: 3 | H17: 8 | I17: 9 | J17: 10 | K17: 11 | L17: 12 | M17: 13 | N17: 14 | O17: 15 | P17: 16 | Q17: 17 | R17: 18 | V17: 8 | W17: 3
D18: 7 | E18: 2 | G18: 19 | H18: 20 | I18: 21 | J18: 22 | K18: 23 | L18: 24 | M18: 25 | N18: 26 | O18: 27 | P18: 28 | Q18: 29 | R18: 30 | S18: 31 | V18: 7 | W18: 2 | AO18: 14mJ
D19: 6 | E19: 1 | G19: 32 | H19: 33 | I19: 34 | J19: 35 | K19: 36 | L19: 37 | M19: 38 | N19: 39 | O19: 40 | P19: 41 | Q19: 42 | R19: 43 | S19: 44 | V19: 6 | W19: 1 | AO19: 17mJ
D20: 5 | E20: 0 | G20: 45 | H20: 46 | I20: 47 | J20: 48 | K20: 49 | L20: 50 | M20: 51 | N20: 52 | O20: 53 | P20: 54 | Q20: 55 | R20: 56 | S20: 57 | V20: 5 | W20: 0 | AE20: X | AO20: 20mJ
D21: 4 | E21: -1 | G21: 58 | H21: 59 | I21: 60 | J21: 61 | K21: 62 | L21: 63 | M21: 64 | N21: 65 | O21: 66 | P21: 67 | Q21: 68 | R21: 69 | S21: 70 | V21: 4 | W21: -1 | AO21: 23mJ
D22: 3 | E22: -2 | G22: 71 | H22: 72 | I22: 73 | J22: 74 | K22: 75 | L22: 76 | M22: 77 | N22: 78 | O22: 79 | P22: 80 | Q22: 81 | R22: 82 | S22: 83 | V22: 3 | W22: -2
D23: 2 | E23: -3 | H23: 84 | I23: 85 | J23: 86 | K23: 87 | L23: 88 | M23: 89 | N23: 90 | O23: 91 | P23: 92 | Q23: 93 | R23: 94 | V23: 2 | W23: -3
D24: 1 | E24: -4 | J24: 95 | K24: 96 | L24: 97 | M24: 98 | N24: 99 | O24: 100 | P24: 101 | V24: 1 | W24: -4
D25: 0 | E25: -5 | V25: 0 | W25: -5
X27: 0 | Y27: 1 | Z27: 2 | AA27: 3 | AB27: 4 | AC27: 5 | AD27: 6 | AE27: 7 | AF27: 8 | AG27: 9 | AH27: 10 | AI27: 11 | AJ27: 12 | AK27: 13 | AL27: 14
X28: -7 | Y28: -6 | Z28: -5 | AA28: -4 | AB28: -3 | AC28: -2 | AD28: -1 | AE28: 0 | AF28: 1 | AG28: 2 | AH28: 3 | AI28: 4 | AJ28: 5 | AK28: 6 | AL28: 7
V29: 10 | W29: 5
V30: 9 | W30: 4 | AD30: 1 | AE30: 2 | AF30: 3 | AG30: 4 | AH30: 5
V31: 8 | W31: 3 | AB31: 8 | AC31: 9 | AD31: 10 | AE31: 11 | AF31: 12 | AG31: 13 | AH31: 14 | AI31: 15 | AJ31: 16
V32: 7 | W32: 2 | AA32: 19 | AB32: 20 | AC32: 21 | AD32: 22 | AE32: 23 | AF32: 24 | AG32: 25 | AH32: 26 | AI32: 27 | AJ32: 28 | AK32: 29 | AO32: 14mJ
V33: 6 | W33: 1 | AA33: 32 | AB33: 33 | AC33: 34 | AD33: 35 | AE33: 36 | AF33: 37 | AG33: 38 | AH33: 39 | AI33: 40 | AJ33: 41 | AK33: 42 | AO33: 17mJ
V34: 5 | W34: 0 | AA34: 45 | AB34: 46 | AC34: 47 | AD34: 48 | AE34: 49 | AF34: 50 | AG34: 51 | AH34: 52 | AI34: 53 | AJ34: 54 | AK34: 55 | AO34: 20mJ
V35: 4 | W35: -1 | AA35: 58 | AB35: 59 | AC35: 60 | AD35: 61 | AE35: 62 | AF35: 63 | AG35: 64 | AH35: 65 | AI35: 66 | AJ35: 67 | AK35: 68 | AO35: 23mJ
V36: 3 | W36: -2 | AA36: 71 | AB36: 72 | AC36: 73 | AD36: 74 | AE36: 75 | AF36: 76 | AG36: 77 | AH36: 78 | AI36: 79 | AJ36: 80 | AK36: 81
V37: 2 | W37: -3 | AB37: 84 | AC37: 85 | AD37: 86 | AE37: 87 | AF37: 88 | AG37: 89 | AH37: 90 | AI37: 91 | AJ37: 92
V38: 1 | W38: -4 | AD38: 93 | AE38: 94 | AF38: 95 | AG38: 96 | AH38: 97 | AI38: 98 | AJ38: 99
V39: 0 | W39: -5

Sheet PLAN
A1: MPW41
A3: Slot | B3: Wgs | C3: WGs | D3: No of Chips | E3: Duration
A4: 7 | B4: Strip | C4: 6 | D4: 10 | E4: =C4*D4 -> 60
A5: 11 | B5: Strip | C5: 6 | D5: 10 | E5: =C5*D5 -> 60
A6: 12 | B6: Strip | C6: 6 | D6: 10 | E6: =C6*D6 -> 60
B7: Rib | C7: 6 | D7: 10 | E7: =C7*D7 -> 60
A8: 15 | B8: Strip | C8: 6 | D8: 10 | E8: =C8*D8 -> 60
B9: Rib | C9: 6 | D9: 10 | E9: =C9*D9 -> 60
E10: =SUM(E4:E9) -> 360 | F10: mins
E11: =E10/60 -> 6 | F11: hours

Sheet Wafermap loss distribution
W1: SLOT 7 | AC1: (AVG. PROP LOSS = 4.39 DB/CM) | AM1: SLOT 11 | AS1: (AVG. PROP LOSS = 5.04 DB/CM) | BB1: SLOT 12 | BH1: (AVG. PROP LOSS = 4.72 DB/CM) | BQ1: SLOT 15 | BW1: (AVG. PROP LOSS = 4.97 DB/CM)
F2: 1 | G2: 2 | H2: 3 | I2: 4 | J2: 5 | K2: 6 | L2: 7
D3: 8 | E3: 9 | F3: 10 | G3: 11 | H3: 12 | I3: 13 | J3: 14 | K3: 15 | L3: 16 | M3: 17 | N3: 18 | X3: ='Slot 7 '!E5 -> 3.8016985 | AB3: ='Slot 7 '!E6 -> 4.5594944 | BE3: ='Slot 12'!E5 -> 3.0386561 | BT3: ='Slot 15'!E5 -> 3.5583071
C4: 19 | D4: 20 | E4: 21 | F4: 22 | G4: 23 | H4: 24 | I4: 25 | J4: 26 | K4: 27 | L4: 28 | M4: 29 | N4: 30 | O4: 31
C5: 32 | D5: 33 | E5: 34 | F5: 35 | G5: 36 | H5: 37 | I5: 38 | J5: 39 | K5: 40 | L5: 41 | M5: 42 | N5: 43 | O5: 44 | X5: ='Slot 7 '!E8 -> 3.9804323 | Z5: ='Slot 7 '!E9 -> 4.9293885 | AF5: ='Slot 7 '!E11 -> 4.7918199 | AN5: ='Slot 11'!E6 -> 4.9059561 | AP5: ='Slot 11'!E7 -> 5.0255103 | AR5: ='Slot 11'!E8 -> 5.6724267 | BI5: ='Slot 12'!E8 -> 6.8878792
C6: 45 | D6: 46 | E6: 47 | F6: 48 | G6: 49 | H6: 50 | I6: 51 | J6: 52 | K6: 53 | L6: 54 | M6: 55 | N6: 56 | O6: 57 | AO6: ='Slot 11'!E9 -> 5.0594241 | AV6: ='Slot 11'!E10 -> 4.5212136 | BE6: ='Slot 12'!E9 -> 4.9315566 | BH6: ='Slot 12'!E10 -> 6.2792691 | BK6: ='Slot 12'!E11 -> 3.4768161 | BQ6: ='Slot 15'!E9 -> 3.1316735 | BT6: ='Slot 15'!E10 -> 5.9847798 | BZ6: ='Slot 15'!E12 -> 5.9680225
C7: 58 | D7: 59 | E7: 60 | F7: 61 | G7: 62 | H7: 63 | I7: 64 | J7: 65 | K7: 66 | L7: 67 | M7: 68 | N7: 69 | O7: 70 | X7: ='Slot 7 '!E12 -> 4.6096069 | AM7: ='Slot 11'!E11 -> 4.932193 | BG7: ='Slot 12'!E12 -> 5.2923086 | BV7: ='Slot 15'!E13 -> 6.9911106
C8: 71 | D8: 72 | E8: 73 | F8: 74 | G8: 75 | H8: 76 | I8: 77 | J8: 78 | K8: 79 | L8: 80 | M8: 81 | N8: 82 | O8: 83 | AR8: ='Slot 11'!E12 -> 5.1447723 | BC8: ='Slot 12'!E13 -> 3.8239438 | BI8: ='Slot 12'!E14 -> 4.0410067 | BR8: ='Slot 15'!E14 -> 4.2805664 | BX8: ='Slot 15'!E15 -> 4.8450666
D9: 84 | E9: 85 | F9: 86 | G9: 87 | H9: 88 | I9: 89 | J9: 90 | K9: 91 | L9: 92 | M9: 93 | N9: 94 | AB9: ='Slot 7 '!E17 -> 4.050786 | AS9: ='Slot 11'!E13 -> 4.4133392
F10: 95 | G10: 96 | H10: 97 | I10: 98 | J10: 99 | K10: 100 | L10: 101 | AU10: ='Slot 11'!E15 -> 5.6714595
C12: WST | W12: wafer | AM12: wafer
F13: 1 | G13: 2 | H13: 3 | I13: 4 | J13: 5 | K13: 6 | L13: 7 | Z13: 1 | AA13: 2 | AB13: 3 | AC13: 4 | AD13: 5 | AE13: 6 | AF13: 7 | AS13: 1 | AT13: 2 | AU13: 3 | AV13: 4 | AW13: 5 | AX13: 6 | AY13: 7
D14: 8 | E14: 9 | F14: 10 | G14: 11 | H14: 12 | I14: 13 | J14: 14 | K14: 15 | L14: 16 | M14: 17 | N14: 18 | X14: 8 | Y14: 9 | Z14: 10 | AA14: 11 | AB14: 12 | AC14: 13 | AD14: 14 | AE14: 15 | AF14: 16 | AG14: 17 | AH14: 18 | AQ14: 8 | AR14: 9 | AS14: 10 | AT14: 11 | AU14: 12 | AV14: 13 | AW14: 14 | AX14: 15 | AY14: 16 | AZ14: 17 | BA14: 18
C15: 19 | D15: 20 | E15: 21 | F15: 22 | G15: 23 | H15: 24 | I15: 25 | J15: 26 | K15: 27 | L15: 28 | M15: 29 | N15: 30 | O15: 31 | W15: 19 | X15: 20 | Y15: 21 | Z15: 22 | AA15: 23 | AB15: 24 | AC15: 25 | AD15: 26 | AE15: 27 | AF15: 28 | AG15: 29 | AH15: 30 | AI15: 31 | AP15: 19 | AQ15: 20 | AR15: 21 | AS15: 22 | AT15: 23 | AU15: 24 | AV15: 25 | AW15: 26 | AX15: 27 | AY15: 28 | AZ15: 29 | BA15: 30 | BB15: 31
C16: 32 | D16: 33 | E16: 34 | F16: 35 | G16: 36 | H16: 37 | I16: 38 | J16: 39 | K16: 40 | L16: 41 | M16: 42 | N16: 43 | O16: 44 | W16: 32 | X16: 33 | Y16: 34 | Z16: 35 | AA16: 36 | AB16: 37 | AC16: 38 | AD16: 39 | AE16: 40 | AF16: 41 | AG16: 42 | AH16: 43 | AI16: 44 | AP16: 32 | AQ16: 33 | AR16: 34 | AS16: 35 | AT16: 36 | AU16: 37 | AV16: 38 | AW16: 39 | AX16: 40 | AY16: 41 | AZ16: 42 | BA16: 43 | BB16: 44
C17: 45 | D17: 46 | E17: 47 | F17: 48 | G17: 49 | H17: 50 | I17: 51 | J17: 52 | K17: 53 | L17: 54 | M17: 55 | N17: 56 | O17: 57 | W17: 45 | X17: 46 | Y17: 47 | Z17: 48 | AA17: 49 | AB17: 50 | AC17: 51 | AD17: 52 | AE17: 53 | AF17: 54 | AG17: 55 | AH17: 56 | AI17: 57 | AP17: 45 | AQ17: 46 | AR17: 47 | AS17: 48 | AT17: 49 | AU17: 50 | AV17: 51 | AW17: 52 | AX17: 53 | AY17: 54 | AZ17: 55 | BA17: 56 | BB17: 57
C18: 58 | D18: 59 | E18: 60 | F18: 61 | G18: 62 | H18: 63 | I18: 64 | J18: 65 | K18: 66 | L18: 67 | M18: 68 | N18: 69 | O18: 70 | W18: 58 | X18: 59 | Y18: 60 | Z18: 61 | AA18: 62 | AB18: 63 | AC18: 64 | AD18: 65 | AE18: 66 | AF18: 67 | AG18: 68 | AH18: 69 | AI18: 70 | AP18: 58 | AQ18: 59 | AR18: 60 | AS18: 61 | AT18: 62 | AU18: 63 | AV18: 64 | AW18: 65 | AX18: 66 | AY18: 67 | AZ18: 68 | BA18: 69 | BB18: 70
C19: 71 | D19: 72 | E19: 73 | F19: 74 | G19: 75 | H19: 76 | I19: 77 | J19: 78 | K19: 79 | L19: 80 | M19: 81 | N19: 82 | O19: 83 | W19: 71 | X19: 72 | Y19: 73 | Z19: 74 | AA19: 75 | AB19: 76 | AC19: 77 | AD19: 78 | AE19: 79 | AF19: 80 | AG19: 81 | AH19: 82 | AI19: 83 | AP19: 71 | AQ19: 72 | AR19: 73 | AS19: 74 | AT19: 75 | AU19: 76 | AV19: 77 | AW19: 78 | AX19: 79 | AY19: 80 | AZ19: 81 | BA19: 82 | BB19: 83
D20: 84 | E20: 85 | F20: 86 | G20: 87 | H20: 88 | I20: 89 | J20: 90 | K20: 91 | L20: 92 | M20: 93 | N20: 94 | X20: 84 | Y20: 85 | Z20: 86 | AA20: 87 | AB20: 88 | AC20: 89 | AD20: 90 | AE20: 91 | AF20: 92 | AG20: 93 | AH20: 94 | AQ20: 84 | AR20: 85 | AS20: 86 | AT20: 87 | AU20: 88 | AV20: 89 | AW20: 90 | AX20: 91 | AY20: 92 | AZ20: 93 | BA20: 94
F21: 95 | G21: 96 | H21: 97 | I21: 98 | J21: 99 | K21: 100 | L21: 101 | Z21: 95 | AA21: 96 | AB21: 97 | AC21: 98 | AD21: 99 | AE21: 100 | AF21: 101 | AS21: 95 | AT21: 96 | AU21: 97 | AV21: 98 | AW21: 99 | AX21: 100 | AY21: 101

Sheet Bottom notch (NEW) (2)
D2: SLOT 7 | AA2: SLOT 7
F3: REFERENCE | AC3: REFERENCE
F4: Columns | AC4: Columns
F5: 0 | G5: 1 | H5: 2 | I5: 3 | J5: 4 | K5: 5 | L5: 6 | M5: 7 | N5: 8 | O5: 9 | P5: 10 | Q5: 11 | R5: 12 | S5: 13 | T5: 14 | AC5: 0 | AD5: 1 | AE5: 2 | AF5: 3 | AG5: 4 | AH5: 5 | AI5: 6 | AJ5: 7 | AK5: 8 | AL5: 9 | AM5: 10 | AN5: 11 | AO5: 12 | AP5: 13 | AQ5: 14
F6: -7 | G6: -6 | H6: -5 | I6: -4 | J6: -3 | K6: -2 | L6: -1 | M6: 0 | N6: 1 | O6: 2 | P6: 3 | Q6: 4 | R6: 5 | S6: 6 | T6: 7 | AC6: -7 | AD6: -6 | AE6: -5 | AF6: -4 | AG6: -3 | AH6: -2 | AI6: -1 | AJ6: 0 | AK6: 1 | AL6: 2 | AM6: 3 | AN6: 4 | AO6: 5 | AP6: 6 | AQ6: 7
C7: Rows | D7: 10 | E7: 5 | Z7: Rows | AA7: 10 | AB7: 5
D8: 9 | E8: 4 | J8: 1 | K8: 2 | L8: 3 | M8: 4 | N8: 5 | O8: 6 | P8: 7 | AA8: 9 | AB8: 4 | AG8: 1 | AH8: 2 | AI8: 3 | AJ8: 4 | AK8: 5 | AL8: 6 | AM8: 7
D9: 8 | E9: 3 | H9: 8 | I9: 9 | J9: 10 | K9: 3.8016985 | O9: 4.5594944 | AA9: 8 | AB9: 3 | AE9: 8 | AF9: 9 | AG9: 10 | AH9: 11 | AI9: 12 | AJ9: 13 | AK9: 14 | AL9: 15 | AM9: 16 | AN9: 17 | AO9: 18
D10: 7 | E10: 2 | G10: 19 | H10: 20 | I10: 21 | J10: 22 | AA10: 7 | AB10: 2 | AD10: 19 | AE10: 20 | AF10: 21 | AG10: 22 | AH10: 23 | AI10: 24 | AJ10: 25 | AK10: 26 | AL10: 27 | AM10: 28 | AN10: 29 | AO10: 30 | AP10: 31
D11: 6 | E11: 1 | G11: 32 | H11: 33 | I11: 34 | J11: 35 | K11: 3.9804323 | M11: 4.9293885 | S11: 4.7918199 | AA11: 6 | AB11: 1 | AD11: 32 | AE11: 33 | AF11: 34 | AG11: 35 | AH11: 36 | AI11: 37 | AJ11: 38 | AK11: 39 | AL11: 40 | AM11: 41 | AN11: 42 | AO11: 43 | AP11: 44
D12: 5 | E12: 0 | G12: 45 | H12: 46 | I12: 47 | J12: 48 | AA12: 5 | AB12: 0 | AD12: 45 | AE12: 46 | AF12: 47 | AG12: 48 | AH12: 49 | AI12: 50 | AJ12: 51 | AK12: 52 | AL12: 53 | AM12: 54 | AN12: 55 | AO12: 56 | AP12: 57
D13: 4 | E13: -1 | G13: 58 | H13: 59 | I13: 60 | J13: 61 | K13: 4.6096069 | AA13: 4 | AB13: -1 | AD13: 58 | AE13: 59 | AF13: 60 | AG13: 61 | AH13: 62 | AI13: 63 | AJ13: 64 | AK13: 65 | AL13: 66 | AM13: 67 | AN13: 68 | AO13: 69 | AP13: 70
D14: 3 | E14: -2 | G14: 71 | H14: 72 | I14: 73 | J14: 74 | AA14: 3 | AB14: -2 | AD14: 71 | AE14: 72 | AF14: 73 | AG14: 74 | AH14: 75 | AI14: 76 | AJ14: 77 | AK14: 78 | AL14: 79 | AM14: 80 | AN14: 81 | AO14: 82 | AP14: 83
D15: 2 | E15: -3 | H15: 84 | I15: 85 | J15: 86 | O15: 4.050786 | AA15: 2 | AB15: -3 | AE15: 84 | AF15: 85 | AG15: 86 | AH15: 87 | AI15: 88 | AJ15: 89 | AK15: 90 | AL15: 91 | AM15: 92 | AN15: 93 | AO15: 94
D16: 1 | E16: -4 | J16: 95 | K16: 96 | L16: 97 | M16: 98 | N16: 99 | O16: 100 | P16: 101 | AA16: 1 | AB16: -4 | AG16: 95 | AH16: 96 | AI16: 97 | AJ16: 98 | AK16: 99 | AL16: 100 | AM16: 101
D17: 0 | E17: -5 | AA17: 0 | AB17: -5

Sheet Bottom notch (NEW)
F3: REFERENCE
F4: Columns
F5: 0 | G5: 1 | H5: 2 | I5: 3 | J5: 4 | K5: 5 | L5: 6 | M5: 7 | N5: 8 | O5: 9 | P5: 10 | Q5: 11 | R5: 12 | S5: 13 | T5: 14 | AB5: row | AC5: 9
F6: -7 | G6: -6 | H6: -5 | I6: -4 | J6: -3 | K6: -2 | L6: -1 | M6: 0 | N6: 1 | O6: 2 | P6: 3 | Q6: 4 | R6: 5 | S6: 6 | T6: 7 | AB6: column | AC6: 13
C7: Rows | D7: 10 | E7: 5
D8: 9 | E8: 4 | J8: 1 | K8: 2 | L8: 3 | M8: 4 | N8: 5 | O8: 6 | P8: 7
D9: 8 | E9: 3 | H9: 8 | I9: 9 | J9: 10 | K9: 11 | L9: 12 | M9: 13 | N9: 14 | O9: 15 | P9: 16 | Q9: 17 | R9: 18
D10: 7 | E10: 2 | G10: 19 | H10: 20 | I10: 21 | J10: 22 | K10: 23 | L10: 24 | M10: 25 | N10: 26 | O10: 27 | P10: 28 | Q10: 29 | R10: 30 | S10: 31
D11: 6 | E11: 1 | G11: 32 | H11: 33 | I11: 34 | J11: 35 | K11: 36 | L11: 37 | M11: 38 | N11: 39 | O11: 40 | P11: 41 | Q11: 42 | R11: 43 | S11: 44
D12: 5 | E12: 0 | G12: 45 | H12: 46 | I12: 47 | J12: 48 | K12: 49 | L12: 50 | M12: 51 | N12: 52 | O12: 53 | P12: 54 | Q12: 55 | R12: 56 | S12: 57
D13: 4 | E13: -1 | G13: 58 | H13: 59 | I13: 60 | J13: 61 | K13: 62 | L13: 63 | M13: 64 | N13: 65 | O13: 66 | P13: 67 | Q13: 68 | R13: 69 | S13: 70
D14: 3 | E14: -2 | G14: 71 | H14: 72 | I14: 73 | J14: 74 | K14: 75 | L14: 76 | M14: 77 | N14: 78 | O14: 79 | P14: 80 | Q14: 81 | R14: 82 | S14: 83
D15: 2 | E15: -3 | H15: 84 | I15: 85 | J15: 86 | K15: 87 | L15: 88 | M15: 89 | N15: 90 | O15: 91 | P15: 92 | Q15: 93 | R15: 94
D16: 1 | E16: -4 | J16: 95 | K16: 96 | L16: 97 | M16: 98 | N16: 99 | O16: 100 | P16: 101
D17: 0 | E17: -5

Sheet Sheet5
B3: 8 | C3: 3.8016985 | D3: 0.065715203 | G3: 1 | H3: 4.7761623 | I3: 2.4443262 | K3: 10 | L3: 3.0386561 | M3: 0.029479292 | O3: 10 | P3: 3.56 | Q3: 0.03
B4: 12 | C4: 4.5594944 | D4: 0.082247904 | G4: 33 | H4: 4.9059561 | I4: 0.045757777 | K4: 24 | L4: 7.5788104 | M4: 0.28597487 | O4: 24 | P4: 7.02 | Q4: 0.13
B5: 16 | C5: 10.707618 | D5: 35.209953 | G5: 35 | H5: 5.0255103 | I5: 0.028879588 | K5: 36 | L5: 8.5278177 | M5: 0.72200393 | O5: 36 | P5: 9.83 | Q5: 1
B6: 33 | C6: 3.9804323 | D6: 0.028292244 | G6: 37 | H6: 5.6724267 | I6: 0.013169828 | K6: 39 | L6: 6.8878792 | M6: 0.022577854 | O6: 39 | P6: 6.64 | Q6: 0.21
B7: 35 | C7: 4.9293885 | D7: 0.03434945 | G7: 47 | H7: 5.0594241 | I7: 0.026731825 | K7: 48 | L7: 4.9315566 | M7: 0.016351369 | O7: 45 | P7: 3.13 | Q7: 0.02
B8: 37 | C8: 12.855391 | D8: 117.3038 | G8: 54 | H8: 4.5212136 | I8: 0.0078438196 | K8: 51 | L8: 6.2792691 | M8: 0.016077686 | O8: 48 | P8: 5.98 | Q8: 0.02
B9: 41 | C9: 4.7918199 | D9: 0.018803199 | G9: 58 | H9: 4.932193 | I9: 0.026034511 | K9: 54 | L9: 3.4768161 | M9: 0.006000173 | O9: 51 | P9: 7.2 | Q9: 0.19
B10: 59 | C10: 4.6096069 | D10: 0.054239011 | G10: 76 | H10: 5.1447723 | I10: 0.018529104 | K10: 63 | L10: 5.2923086 | M10: 0.072220967 | O10: 54 | P10: 5.97 | Q10: 0.06
B11: 63 | C11: 13.828746 | D11: 66.234408 | G11: 89 | H11: 4.4133392 | I11: 0.015171549 | K11: 72 | L11: 3.8239438 | M11: 0.056732106 | O11: 63 | P11: 6.99 | Q11: 0.08
B12: 65 | C12: 9.3619678 | D12: 84.875878 | G12: 95 | H12: 11.423871 | I12: 98.214409 | K12: 78 | L12: 4.0410067 | M12: 0.014557971 | O12: 72 | P12: 4.28 | Q12: 0.01
B13: 67 | C13: 11.399911 | D13: 65.898217 | G13: 100 | H13: 5.6714595 | I13: 0.019404283 | O13: 78 | P13: 4.85 | Q13: 0.1
B14: 84 | C14: 13.160419 | D14: 103.22497
B15: 88 | C15: 4.050786 | D15: 0.027279707
B16: 92 | C16: 17.982148 | D16: 75.478759 | K16: 10 | L16: 3.56 | M16: 0.03
K17: 24 | L17: 7.02 | M17: 0.13
K18: 36 | L18: 9.83 | M18: 1
K19: 39 | L19: 6.64 | M19: 0.21
K20: 45 | L20: 3.13 | M20: 0.02
K21: 48 | L21: 5.98 | M21: 0.02
K22: 51 | L22: 7.2 | M22: 0.19
K23: 54 | L23: 5.97 | M23: 0.06
K24: 63 | L24: 6.99 | M24: 0.08
K25: 72 | L25: 4.28 | M25: 0.01
K26: 78 | L26: 4.85 | M26: 0.1

Sheet Slot 7 
A1: WAFER ID | B1: Platform | D1: Reticle title | E1: Slot | F1: Wavelength | G1: Wg length
A2: MPW41 | B2: 220nm SOI | E2: 7 | F2: 1550
A4: No | B4: Waveguide | C4: Type | D4: Chip | E4: Propagation loss (dB/cm)/ (dB/unit) | F4: MSE | G4: Date | H4: Status | I4: Comment | J4: Further action
A5: 1 | B5: Straight | C5: Strip | D5: 8 | E5: 3.8016985 | F5: 0.065715203
A6: 2 | D6: 12 | E6: 4.5594944 | F6: 0.082247904
A7: 3 | D7: 16 | E7: 10.707618 | F7: 35.209953
A8: 4 | D8: 33 | E8: 3.9804323 | F8: 0.028292244
A9: 5 | D9: 35 | E9: 4.9293885 | F9: 0.03434945
A10: 6 | D10: 37 | E10: 12.855391 | F10: 117.3038
A11: 7 | D11: 41 | E11: 4.7918199 | F11: 0.018803199
A12: 8 | D12: 59 | E12: 4.6096069 | F12: 0.054239011
A13: 9 | D13: 63 | E13: 13.828746 | F13: 66.234408
D14: 65 | E14: 9.3619678 | F14: 84.875878
D15: 67 | E15: 11.399911 | F15: 65.898217
D16: 84 | E16: 13.160419 | F16: 103.22497
D17: 88 | E17: 4.050786 | F17: 0.027279707
A18: 10 | D18: 92 | E18: 17.982148 | F18: 75.478759
A19: 10 | B19: Straight | D19: AVERAGE | E19: =AVERAGE(E5:E6,E8:E9,E11:E12,E17) -> 4.3890323
A20: 11
A21: 12
A22: 13
A23: 14
A24: 15
A25: 16
A26: 17
A27: 18
A28: 19
A29: 20
A30: 20 | D30: AVERAGE | E30: =AVERAGE(E21,E22,E23,E27) -> #DIV/0!

Sheet Slot 11
A1: WAFER ID | B1: Platform | D1: Reticle title | E1: Slot | F1: Wavelength | G1: Wg length
A2: MPW41 | B2: 220nm SOI | E2: 11 | F2: 1550
A4: No | B4: Waveguide | C4: Type | D4: Chip | E4: Propagation loss (dB/cm)/ (dB/unit) | F4: MSE | G4: Date | H4: Status | I4: Comment | J4: Further action
A5: 1 | B5: Straight | C5: Strip | D5: 1 | E5: 4.7761623 | F5: 2.4443262
A6: 2 | D6: 33 | E6: 4.9059561 | F6: 0.045757777
A7: 3 | D7: 35 | E7: 5.0255103 | F7: 0.028879588
A8: 4 | D8: 37 | E8: 5.6724267 | F8: 0.013169828
A9: 5 | D9: 47 | E9: 5.0594241 | F9: 0.026731825
A10: 6 | D10: 54 | E10: 4.5212136 | F10: 0.0078438196
A11: 7 | D11: 58 | E11: 4.932193 | F11: 0.026034511
A12: 8 | D12: 76 | E12: 5.1447723 | F12: 0.018529104
A13: 9 | D13: 89 | E13: 4.4133392 | F13: 0.015171549
D14: 95 | E14: 11.423871 | F14: 98.214409
D15: 100 | E15: 5.6714595 | F15: 0.019404283
A18: 10
A19: 10 | B19: Straight | D19: AVERAGE | E19: =AVERAGE(E6:E13,E15) -> 5.0384772
A20: 11
A21: 12
A22: 13
A23: 14
A24: 15
A25: 16
A26: 17
A27: 18
A28: 19
A29: 20
A30: 20 | D30: AVERAGE | E30: =AVERAGE(E21,E22,E23,E27) -> #DIV/0!

Sheet Slot 12
A1: WAFER ID | B1: Platform | D1: Reticle title | E1: Slot | F1: Wavelength | G1: Wg length
A2: MPW41 | B2: 220nm SOI | E2: 12 | F2: 1550
A4: No | B4: Waveguide | C4: Type | D4: Chip | E4: Propagation loss (dB/cm)/ (dB/unit) | F4: MSE | G4: Date | H4: Status | I4: Comment | J4: Further action
A5: 1 | B5: Straight | C5: Strip | D5: 10 | E5: 3.0386561 | F5: 0.029479292
A6: 2 | D6: 24 | E6: 7.0545807 | F6: 0.20910891 | I6: remove wg5
A7: 3 | D7: 36 | E7: 7.559376 | F7: 0.33270249 | I7: remove wg5
A8: 4 | D8: 39 | E8: 6.8878792 | F8: 0.022577854
A9: 5 | D9: 48 | E9: 4.9315566 | F9: 0.016351369
A10: 6 | D10: 51 | E10: 6.2792691 | F10: 0.016077686
A11: 7 | D11: 54 | E11: 3.4768161 | F11: 0.006000173
A12: 8 | D12: 63 | E12: 5.2923086 | F12: 0.072220967
A13: 9 | D13: 72 | E13: 3.8239438 | F13: 0.056732106
D14: 78 | E14: 4.0410067 | F14: 0.014557971
A18: 10
A19: 10 | B19: Straight | D19: AVERAGE | E19: =AVERAGE(E5,E8:E14) -> 4.7214295
A20: 11
A21: 12
A22: 13
A23: 14
A24: 15
A25: 16
A26: 17
A27: 18
A28: 19
A29: 20
A30: 20 | D30: AVERAGE | E30: =AVERAGE(E21,E22,E23,E27) -> #DIV/0!

Sheet Slot 15
A1: WAFER ID | B1: Platform | D1: Reticle title | E1: Slot | F1: Wavelength | G1: Wg length
A2: MPW41 | B2: 220nm SOI | E2: 12 | F2: 1550
A4: No | B4: Waveguide | C4: Type | D4: Chip | E4: Propagation loss (dB/cm)/ (dB/unit) | F4: MSE | G4: Date | H4: Status | I4: Comment | J4: Further action
A5: 1 | B5: Straight | C5: Strip | D5: 10 | E5: 3.5583071 | F5: 0.028701681
A6: 2 | D6: 24 | E6: 7.016 | F6: 0.12738722
A7: 3 | D7: 36 | E7: 9.8272975 | F7: 0.99959245
A8: 4 | D8: 39 | E8: 6.6435752 | F8: 0.21156649
A9: 5 | D9: 45 | E9: 3.1316735 | F9: 0.021843169
A10: 6 | D10: 48 | E10: 5.9847798 | F10: 0.023518732
A11: 7 | D11: 51 | E11: 7.2005417 | F11: 0.1889756
A12: 8 | D12: 54 | E12: 5.9680225 | F12: 0.059906563
A13: 9 | D13: 63 | E13: 6.9911106 | F13: 0.082693401
D14: 72 | E14: 4.2805664 | F14: 0.006944013
D15: 78 | E15: 4.8450666 | F15: 0.10114545
A18: 10
A19: 10 | B19: Straight | D19: AVERAGE | E19: =AVERAGE(E5,E9:E10,E12:E15) -> 4.9656466
A20: 11 | D20: 10 | E20: 3.5427982 | F20: 0.0428601
A21: 12 | D21: 24 | E21: 7.4253167 | F21: 0.057048755 | I21: removed wg5
